Workbook

Sheet 彙總統計
A1: 四大會計師事務所 執業會計師人數彙總
A2: 資料來源：中華民國會計師公會全國聯合會「執業入會查詢－全國聯合會」(https://www.roccpa.org.tw/member_search/)
A3: 擷取日期：2026-09-10 範圍：查詢狀態為「可執業」之執業登記會計師，共 498 位
A5: 事務所 | B5: 台北總所 | C5: 桃園分所 | D5: 新竹分所 | E5: 台中分所 | F5: 台南分所 | G5: 高雄分所 | H5: 合計
A6: Deloitte 勤業眾信 | B6: =COUNTIFS(全部名單!$B$2:$B$499,"勤業眾信聯合會計師事務所",全部名單!$E$2:$E$499,"台北總所") | C6: =COUNTIFS(全部名單!$B$2:$B$499,"勤業眾信聯合會計師事務所",全部名單!$E$2:$E$499,"桃園分所") | D6: =COUNTIFS(全部名單!$B$2:$B$499,"勤業眾信聯合會計師事務所",全部名單!$E$2:$E$499,"新竹分所") | E6: =COUNTIFS(全部名單!$B$2:$B$499,"勤業眾信聯合會計師事務所",全部名單!$E$2:$E$499,"台中分所") | F6: =COUNTIFS(全部名單!$B$2:$B$499,"勤業眾信聯合會計師事務所",全部名單!$E$2:$E$499,"台南分所") | G6: =COUNTIFS(全部名單!$B$2:$B$499,"勤業眾信聯合會計師事務所",全部名單!$E$2:$E$499,"高雄分所") | H6: =SUM(B6:G6)
A7: PwC 資誠 | B7: =COUNTIFS(全部名單!$B$2:$B$499,"資誠聯合會計師事務所",全部名單!$E$2:$E$499,"台北總所") | C7: =COUNTIFS(全部名單!$B$2:$B$499,"資誠聯合會計師事務所",全部名單!$E$2:$E$499,"桃園分所") | D7: =COUNTIFS(全部名單!$B$2:$B$499,"資誠聯合會計師事務所",全部名單!$E$2:$E$499,"新竹分所") | E7: =COUNTIFS(全部名單!$B$2:$B$499,"資誠聯合會計師事務所",全部名單!$E$2:$E$499,"台中分所") | F7: =COUNTIFS(全部名單!$B$2:$B$499,"資誠聯合會計師事務所",全部名單!$E$2:$E$499,"台南分所") | G7: =COUNTIFS(全部名單!$B$2:$B$499,"資誠聯合會計師事務所",全部名單!$E$2:$E$499,"高雄分所") | H7: =SUM(B7:G7)
A8: KPMG 安侯建業 | B8: =COUNTIFS(全部名單!$B$2:$B$499,"安侯建業聯合會計師事務所",全部名單!$E$2:$E$499,"台北總所") | C8: =COUNTIFS(全部名單!$B$2:$B$499,"安侯建業聯合會計師事務所",全部名單!$E$2:$E$499,"桃園分所") | D8: =COUNTIFS(全部名單!$B$2:$B$499,"安侯建業聯合會計師事務所",全部名單!$E$2:$E$499,"新竹分所") | E8: =COUNTIFS(全部名單!$B$2:$B$499,"安侯建業聯合會計師事務所",全部名單!$E$2:$E$499,"台中分所") | F8: =COUNTIFS(全部名單!$B$2:$B$499,"安侯建業聯合會計師事務所",全部名單!$E$2:$E$499,"台南分所") | G8: =COUNTIFS(全部名單!$B$2:$B$499,"安侯建業聯合會計師事務所",全部名單!$E$2:$E$499,"高雄分所") | H8: =SUM(B8:G8)
A9: EY 安永 | B9: =COUNTIFS(全部名單!$B$2:$B$499,"安永聯合會計師事務所",全部名單!$E$2:$E$499,"台北總所") | C9: =COUNTIFS(全部名單!$B$2:$B$499,"安永聯合會計師事務所",全部名單!$E$2:$E$499,"桃園分所") | D9: =COUNTIFS(全部名單!$B$2:$B$499,"安永聯合會計師事務所",全部名單!$E$2:$E$499,"新竹分所") | E9: =COUNTIFS(全部名單!$B$2:$B$499,"安永聯合會計師事務所",全部名單!$E$2:$E$499,"台中分所") | F9: =COUNTIFS(全部名單!$B$2:$B$499,"安永聯合會計師事務所",全部名單!$E$2:$E$499,"台南分所") | G9: =COUNTIFS(全部名單!$B$2:$B$499,"安永聯合會計師事務所",全部名單!$E$2:$E$499,"高雄分所") | H9: =SUM(B9:G9)
A10: 合計 | B10: =SUM(B6:B9) | C10: =SUM(C6:C9) | D10: =SUM(D6:D9) | E10: =SUM(E6:E9) | F10: =SUM(F6:F9) | G10: =SUM(G6:G9) | H10: =SUM(H6:H9)
A12: 欄位說明
A13: 1. 「所屬分所」係依網站「分事務所地址」欄位之縣市自動歸類；該欄位空白者歸為「台北總所」（即主事務所所在地）。
A14: 2. 「辦公室地址」＝有分事務所地址者取分事務所地址，否則取主事務所地址。
A15: 3. 「所屬公會」代碼：北市＝台北市會計師公會、中市＝臺中市會計師公會、高市＝高雄市會計師公會、省＝臺灣省會計師公會。
A16: 4. 本表僅含全國聯合會執業登記名單，未含各地方公會另行登錄但未完成全聯會執業登記者。
A17: 5. 同一會計師若同時登記主事務所與分事務所，網站僅提供一組分事務所地址，故一人僅歸屬一個分所。

Sheet 全部名單
A1: 序號 | B1: 事務所名稱 | C1: 國際品牌 | D1: 會計師姓名 | E1: 所屬分所 | F1: 辦公室地址 | G1: 主事務所地址 | H1: 分事務所地址 | I1: 執業登記日期 | J1: 執業登記文號 | K1: 所屬公會 | L1: 入會日期 | M1: 會籍編號 | N1: 資料最後更新日 | O1: 明細連結
A2: 1 | B2: 勤業眾信聯合會計師事務所 | C2: Deloitte 勤業眾信 | D2: 侯玉燡 | E2: 台北總所 | F2: 台北市信義區松仁路100號20樓 | G2: 台北市信義區松仁路100號20樓 | I2: 110/06/09 | J2: 全聯會一字第1100233 | K2: 北市 | L2: 110/06/09 | M2: 4338 | N2: 2026-06-05 | O2: https://www.roccpa.org.tw/member_search/more?id=3005F4E1-61C5-4100-8FF0-5BF2F667E759
A3: 2 | B3: 勤業眾信聯合會計師事務所 | C3: Deloitte 勤業眾信 | D3: 劉力維 | E3: 台北總所 | F3: 台北市信義區松仁路100號20樓 | G3: 台北市信義區松仁路100號20樓 | I3: 111/06/10 | J3: 全聯會一字第1110221 | K3: 北市 | L3: 111/06/10 | M3: 4433 | N3: 2026-06-05 | O3: https://www.roccpa.org.tw/member_search/more?id=6423F685-3F47-4E0E-A3B1-8DCE4666C896
A4: 3 | B4: 勤業眾信聯合會計師事務所 | C4: Deloitte 勤業眾信 | D4: 劉建良 | E4: 台北總所 | F4: 台北市信義區松仁路100號20樓 | G4: 台北市信義區松仁路100號20樓 | I4: 100/05/25 | J4: 全聯會一字第1000207 | K4: 北市 | L4: 100/06/07 | M4: 3354 | N4: 2026-06-05 | O4: https://www.roccpa.org.tw/member_search/more?id=80DA8D03-FCFC-42D8-A83E-38EA6AF532F3
A5: 4 | B5: 勤業眾信聯合會計師事務所 | C5: Deloitte 勤業眾信 | D5: 劉怡青 | E5: 台北總所 | F5: 台北市信義區松仁路100號20樓 | G5: 台北市信義區松仁路100號20樓 | I5: 110/06/09 | J5: 全聯會一字第1100225 | K5: 北市 | L5: 110/06/09 | M5: 4330 | N5: 2026-06-05 | O5: https://www.roccpa.org.tw/member_search/more?id=D91CD5AA-C9AA-4CD0-86EF-DAA5002E83E3
A6: 5 | B6: 勤業眾信聯合會計師事務所 | C6: Deloitte 勤業眾信 | D6: 劉振宇 | E6: 台北總所 | F6: 台北市信義區松仁路100號20樓 | G6: 台北市信義區松仁路100號20樓 | I6: 115/06/15 | J6: 全聯會一字第1150000289號 | K6: 北市 | L6: 115/06/15 | M6: 4896 | N6: 2026-06-23 | O6: https://www.roccpa.org.tw/member_search/more?id=f982591700b54d4b89e36c33ea8fc556
A7: 6 | B7: 勤業眾信聯合會計師事務所 | C7: Deloitte 勤業眾信 | D7: 劉明賢 | E7: 台北總所 | F7: 台北市信義區松仁路100號20樓 | G7: 台北市信義區松仁路100號20樓 | I7: 110/06/09 | J7: 全聯會一字第1100227 | K7: 北市 | L7: 110/06/09 | M7: 4332 | N7: 2026-06-05 | O7: https://www.roccpa.org.tw/member_search/more?id=DC8924EE-20A9-41B4-9C6B-8A49FE225275
A8: 7 | B8: 勤業眾信聯合會計師事務所 | C8: Deloitte 勤業眾信 | D8: 劉書琳 | E8: 台北總所 | F8: 台北市信義區松仁路100號20樓 | G8: 台北市信義區松仁路100號20樓 | I8: 105/06/01 | J8: 全聯會一字第1050250 | K8: 北市 | L8: 105/06/13 | M8: 3937 | N8: 2026-06-05 | O8: https://www.roccpa.org.tw/member_search/more?id=D11D583E-46D4-4239-993F-6658FF47F152
A9: 8 | B9: 勤業眾信聯合會計師事務所 | C9: Deloitte 勤業眾信 | D9: 劉紋伶 | E9: 台北總所 | F9: 台北市信義區松仁路100號20樓 | G9: 台北市信義區松仁路100號20樓 | I9: 113/06/19 | J9: 全聯會一字第1130000278號 | K9: 北市 | L9: 113/06/19 | M9: 4635 | N9: 2026-06-05 | O9: https://www.roccpa.org.tw/member_search/more?id=ABC7DC62-E5AF-4C2F-ACE1-9D39DB9D0037
A10: 9 | B10: 勤業眾信聯合會計師事務所 | C10: Deloitte 勤業眾信 | D10: 劉紋廷 | E10: 台北總所 | F10: 台北市信義區松仁路100號20樓 | G10: 台北市信義區松仁路100號20樓 | I10: 115/06/15 | J10: 全聯會一字第1150000284號 | K10: 北市 | L10: 115/06/15 | M10: 4901 | N10: 2026-06-23 | O10: https://www.roccpa.org.tw/member_search/more?id=827ae8718493401f9576d5ac9eb5be76
A11: 10 | B11: 勤業眾信聯合會計師事務所 | C11: Deloitte 勤業眾信 | D11: 吳世宗 | E11: 台北總所 | F11: 台北市信義區松仁路100號20樓 | G11: 台北市信義區松仁路100號20樓 | I11: 101/06/04 | J11: 全聯會一字第1010178 | K11: 北市 | L11: 101/06/14 | M11: 3470 | N11: 2026-06-05 | O11: https://www.roccpa.org.tw/member_search/more?id=4BE1AABB-8682-4922-95B3-2FEEBBB5A0DD
A12: 11 | B12: 勤業眾信聯合會計師事務所 | C12: Deloitte 勤業眾信 | D12: 吳怡君 | E12: 台北總所 | F12: 台北市信義區松仁路100號20樓 | G12: 台北市信義區松仁路100號20樓 | K12: 北市 | L12: 093/06/10 | M12: 2661 | N12: 2026-06-05 | O12: https://www.roccpa.org.tw/member_search/more?id=0DC99E99-351F-4F1D-BAED-551C3F32F43D
A13: 12 | B13: 勤業眾信聯合會計師事務所 | C13: Deloitte 勤業眾信 | D13: 吳恪昌 | E13: 台北總所 | F13: 台北市信義區松仁路100號20樓 | G13: 台北市信義區松仁路100號20樓 | I13: 100/05/25 | J13: 全聯會一字第1000210 | K13: 北市 | L13: 100/06/07 | M13: 3357 | N13: 2026-06-05 | O13: https://www.roccpa.org.tw/member_search/more?id=F4BF39AB-F306-4487-AFFC-66B1626B79E4
A14: 13 | B14: 勤業眾信聯合會計師事務所 | C14: Deloitte 勤業眾信 | D14: 吳美慧 | E14: 台北總所 | F14: 台北市信義區松仁路100號20樓 | G14: 台北市信義區松仁路100號20樓 | K14: 北市 | L14: 089/11/13 | M14: 2301 | N14: 2026-06-05 | O14: https://www.roccpa.org.tw/member_search/more?id=E1B90370-7D87-474A-9A11-D7F24C193C45
A15: 14 | B15: 勤業眾信聯合會計師事務所 | C15: Deloitte 勤業眾信 | D15: 吳鈞麟 | E15: 台北總所 | F15: 台北市信義區松仁路100號20樓 | G15: 台北市信義區松仁路100號20樓 | I15: 113/06/19 | J15: 全聯會一字第1130000280號 | K15: 北市 | L15: 113/06/19 | M15: 4637 | N15: 2026-06-05 | O15: https://www.roccpa.org.tw/member_search/more?id=6BB7B9CF-C767-45A3-B123-8BD038D8916E
A16: 15 | B16: 勤業眾信聯合會計師事務所 | C16: Deloitte 勤業眾信 | D16: 呂宜真 | E16: 台北總所 | F16: 台北市信義區松仁路100號20樓 | G16: 台北市信義區松仁路100號20樓 | I16: 108/06/12 | J16: 全聯會一字第1080207 | K16: 北市 | L16: 108/06/12 | M16: 4171 | N16: 2026-06-05 | O16: https://www.roccpa.org.tw/member_search/more?id=F1F0537D-0184-4092-A7C1-E45D63985B2D
A17: 16 | B17: 勤業眾信聯合會計師事務所 | C17: Deloitte 勤業眾信 | D17: 呂相瑩 | E17: 台北總所 | F17: 台北市信義區松仁路100號20樓 | G17: 台北市信義區松仁路100號20樓 | I17: 112/06/08 | J17: 全聯會一字第1120224 | K17: 北市 | L17: 112/06/08 | M17: 4530 | N17: 2026-06-05 | O17: https://www.roccpa.org.tw/member_search/more?id=50490783-E4EC-4921-932A-A645450346E7
A18: 17 | B18: 勤業眾信聯合會計師事務所 | C18: Deloitte 勤業眾信 | D18: 周仕杰 | E18: 台北總所 | F18: 台北市信義區松仁路100號20樓 | G18: 台北市信義區松仁路100號20樓 | I18: 111/06/10 | J18: 全聯會一字第1110217 | K18: 北市 | L18: 111/06/10 | M18: 4429 | N18: 2026-06-05 | O18: https://www.roccpa.org.tw/member_search/more?id=BB7E2A76-0446-4D87-A31D-0535B4848099
A19: 18 | B19: 勤業眾信聯合會計師事務所 | C19: Deloitte 勤業眾信 | D19: 周以隆 | E19: 台北總所 | F19: 台北市信義區松仁路100號20樓 | G19: 台北市信義區松仁路100號20樓 | K19: 北市 | L19: 093/06/10 | M19: 2654 | N19: 2026-06-05 | O19: https://www.roccpa.org.tw/member_search/more?id=BD0A1037-DB4C-436E-95E7-55F395ABBD68
A20: 19 | B20: 勤業眾信聯合會計師事務所 | C20: Deloitte 勤業眾信 | D20: 周正國 | E20: 台北總所 | F20: 台北市信義區松仁路100號20樓 | G20: 台北市信義區松仁路100號20樓 | I20: 115/06/15 | J20: 全聯會一字第1150000285號 | K20: 北市 | L20: 115/06/15 | M20: 4892 | N20: 2026-06-23 | O20: https://www.roccpa.org.tw/member_search/more?id=848f6c9fd2984866a3adab8e1355f8c1
A21: 20 | B21: 勤業眾信聯合會計師事務所 | C21: Deloitte 勤業眾信 | D21: 姚勝雄 | E21: 台北總所 | F21: 台北市信義區松仁路100號20樓 | G21: 台北市信義區松仁路100號20樓 | I21: 101/06/04 | J21: 全聯會一字第1010179 | K21: 北市 | L21: 101/06/14 | M21: 3471 | N21: 2026-06-05 | O21: https://www.roccpa.org.tw/member_search/more?id=A622E5B3-327A-42A0-891F-354E8A10874F
A22: 21 | B22: 勤業眾信聯合會計師事務所 | C22: Deloitte 勤業眾信 | D22: 婁朧允 | E22: 台北總所 | F22: 台北市信義區松仁路100號20樓 | G22: 台北市信義區松仁路100號20樓 | I22: 113/06/19 | J22: 全聯會一字第1130000285號 | K22: 北市 | L22: 113/06/19 | M22: 4642 | N22: 2026-06-05 | O22: https://www.roccpa.org.tw/member_search/more?id=9B7805BC-76BC-4F99-8A1A-5368B4B223B2
A23: 22 | B23: 勤業眾信聯合會計師事務所 | C23: Deloitte 勤業眾信 | D23: 尤志峰 | E23: 台北總所 | F23: 台北市信義區松仁路100號20樓 | G23: 台北市信義區松仁路100號20樓 | I23: 114/06/18 | J23: 全聯會一字第1140000240號 | K23: 北市 | L23: 114/06/18 | M23: 4724 | N23: 2026-06-05 | O23: https://www.roccpa.org.tw/member_search/more?id=92D0AF05-9E8B-4FF9-9AD9-64F0108ABC8A
A24: 23 | B24: 勤業眾信聯合會計師事務所 | C24: Deloitte 勤業眾信 | D24: 尤盟貴 | E24: 台北總所 | F24: 台北市信義區松仁路100號20樓 | G24: 台北市信義區松仁路100號20樓 | I24: 113/09/02 | J24: 全聯會一字第1130000400號 | K24: 北市 | L24: 113/09/02 | M24: 4661 | N24: 2026-06-05 | O24: https://www.roccpa.org.tw/member_search/more?id=D7283C06-29A6-4DE9-BD2A-C2654DC37AD2
A25: 24 | B25: 勤業眾信聯合會計師事務所 | C25: Deloitte 勤業眾信 | D25: 康育榮 | E25: 台北總所 | F25: 台北市信義區松仁路100號20樓 | G25: 台北市信義區松仁路100號20樓 | I25: 115/06/15 | J25: 全聯會一字第1150000290號 | K25: 北市 | L25: 115/06/15 | M25: 4897 | N25: 2026-06-23 | O25: https://www.roccpa.org.tw/member_search/more?id=ee3432266cbd4647b4c8ae07e532fd4c
A26: 25 | B26: 勤業眾信聯合會計師事務所 | C26: Deloitte 勤業眾信 | D26: 廖哲莉 | E26: 台北總所 | F26: 台北市信義區松仁路100號20樓 | G26: 台北市信義區松仁路100號20樓 | K26: 北市 | L26: 089/11/13 | M26: 2298 | N26: 2026-06-05 | O26: https://www.roccpa.org.tw/member_search/more?id=68424988-47BA-499B-8D89-682EE399427A
A27: 26 | B27: 勤業眾信聯合會計師事務所 | C27: Deloitte 勤業眾信 | D27: 廖婉怡 | E27: 台北總所 | F27: 台北市信義區松仁路100號20樓 | G27: 台北市信義區松仁路100號20樓 | I27: 101/06/04 | J27: 全聯會一字第1010177 | K27: 北市 | L27: 101/06/14 | M27: 3469 | N27: 2026-06-05 | O27: https://www.roccpa.org.tw/member_search/more?id=248714FA-65F7-4D17-8EBB-9051D13446E7
A28: 27 | B28: 勤業眾信聯合會計師事務所 | C28: Deloitte 勤業眾信 | D28: 廖家琪 | E28: 台北總所 | F28: 台北市信義區松仁路100號20樓 | G28: 台北市信義區松仁路100號20樓 | I28: 109/06/10 | J28: 全聯會一字第1090221 | K28: 北市 | L28: 109/06/10 | M28: 4260 | N28: 2026-06-05 | O28: https://www.roccpa.org.tw/member_search/more?id=0C2E6CB4-6908-48A4-B8AF-62FF19427403
A29: 28 | B29: 勤業眾信聯合會計師事務所 | C29: Deloitte 勤業眾信 | D29: 張哲彥 | E29: 台北總所 | F29: 台北市信義區松仁路100號20樓 | G29: 台北市信義區松仁路100號20樓 | I29: 115/06/15 | J29: 全聯會一字第1150000293號 | K29: 北市 | L29: 115/06/15 | M29: 4900 | N29: 2026-06-23 | O29: https://www.roccpa.org.tw/member_search/more?id=244567f33ca0441188fcb0095e10c1b5
A30: 29 | B30: 勤業眾信聯合會計師事務所 | C30: Deloitte 勤業眾信 | D30: 張嘉銘 | E30: 台北總所 | F30: 台北市信義區松仁路100號20樓 | G30: 台北市信義區松仁路100號20樓 | I30: 114/06/18 | J30: 全聯會一字第1140000241號 | K30: 北市 | L30: 114/06/18 | M30: 4725 | N30: 2026-06-05 | O30: https://www.roccpa.org.tw/member_search/more?id=B66CD394-A7E3-44D9-AEEF-5397956F2629
A31: 30 | B31: 勤業眾信聯合會計師事務所 | C31: Deloitte 勤業眾信 | D31: 張宗銘 | E31: 台北總所 | F31: 台北市信義區松仁路100號20樓 | G31: 台北市信義區松仁路100號20樓 | I31: 099/05/25 | J31: 全聯會一字第09900258 | K31: 北市 | L31: 099/06/04 | M31: 3231 | N31: 2026-06-05 | O31: https://www.roccpa.org.tw/member_search/more?id=CAA6F87C-AD39-469D-9486-D6863E4F543E
A32: 31 | B32: 勤業眾信聯合會計師事務所 | C32: Deloitte 勤業眾信 | D32: 張正修 | E32: 台北總所 | F32: 台北市信義區松仁路100號20樓 | G32: 台北市信義區松仁路100號20樓 | I32: 112/06/08 | J32: 全聯會一字第1120220 | K32: 北市 | L32: 112/06/08 | M32: 4526 | N32: 2026-06-05 | O32: https://www.roccpa.org.tw/member_search/more?id=99645D90-9683-487D-84D5-B799C9A274E2
A33: 32 | B33: 勤業眾信聯合會計師事務所 | C33: Deloitte 勤業眾信 | D33: 張淳儀 | E33: 台北總所 | F33: 台北市信義區松仁路100號20樓 | G33: 台北市信義區松仁路100號20樓 | K33: 北市 | L33: 088/01/29 | M33: 2129 | N33: 2026-06-05 | O33: https://www.roccpa.org.tw/member_search/more?id=633F0845-4E38-4090-AC51-B1EFB13AA945
A34: 33 | B34: 勤業眾信聯合會計師事務所 | C34: Deloitte 勤業眾信 | D34: 張瑞峰 | E34: 台北總所 | F34: 台北市信義區松仁路100號20樓 | G34: 台北市信義區松仁路100號20樓 | I34: 109/06/10 | J34: 全聯會一字第1090214 | K34: 北市 | L34: 109/06/10 | M34: 4253 | N34: 2026-06-05 | O34: https://www.roccpa.org.tw/member_search/more?id=F0292D2E-E20E-431F-BA8A-5077AD9E089B
A35: 34 | B35: 勤業眾信聯合會計師事務所 | C35: Deloitte 勤業眾信 | D35: 張美卿 | E35: 台北總所 | F35: 台北市信義區松仁路100號20樓 | G35: 台北市信義區松仁路100號20樓 | I35: 115/06/15 | J35: 全聯會一字第1150000287號 | K35: 北市 | L35: 115/06/15 | M35: 4894 | N35: 2026-06-23 | O35: https://www.roccpa.org.tw/member_search/more?id=a778492fdcbf4b7596fd9113b85e0c46
A36: 35 | B36: 勤業眾信聯合會計師事務所 | C36: Deloitte 勤業眾信 | D36: 張耿禧 | E36: 台北總所 | F36: 台北市信義區松仁路100號20樓 | G36: 台北市信義區松仁路100號20樓 | K36: 北市 | L36: 090/01/10 | M36: 2333 | N36: 2026-06-05 | O36: https://www.roccpa.org.tw/member_search/more?id=CFDB2A00-A1C4-432F-8693-4343FC0E35F0
A37: 36 | B37: 勤業眾信聯合會計師事務所 | C37: Deloitte 勤業眾信 | D37: 張至誼 | E37: 台北總所 | F37: 台北市信義區松仁路100號20樓 | G37: 台北市信義區松仁路100號20樓 | I37: 109/03/02 | J37: 全聯會一字第1090088 | K37: 北市 | L37: 109/03/02 | M37: 4227 | N37: 2026-06-05 | O37: https://www.roccpa.org.tw/member_search/more?id=2E125208-F858-4843-8CAD-199D8C7C8927
A38: 37 | B38: 勤業眾信聯合會計師事務所 | C38: Deloitte 勤業眾信 | D38: 張雅涵 | E38: 台北總所 | F38: 台北市信義區松仁路100號20樓 | G38: 台北市信義區松仁路100號20樓 | I38: 115/06/15 | J38: 全聯會一字第1150000286號 | K38: 北市 | L38: 115/06/15 | M38: 4893 | N38: 2026-06-23 | O38: https://www.roccpa.org.tw/member_search/more?id=5c684f9c694145659b6a6faa211ca641
A39: 38 | B39: 勤業眾信聯合會計師事務所 | C39: Deloitte 勤業眾信 | D39: 張青霞 | E39: 台北總所 | F39: 台北市信義區松仁路100號20樓 | G39: 台北市信義區松仁路100號20樓 | I39: 109/06/10 | J39: 全聯會一字第1090212 | K39: 北市 | L39: 109/06/10 | M39: 4251 | N39: 2026-06-05 | O39: https://www.roccpa.org.tw/member_search/more?id=36536DF6-1647-428C-A2C4-830E777C6DFE
A40: 39 | B40: 勤業眾信聯合會計師事務所 | C40: Deloitte 勤業眾信 | D40: 張麗君 | E40: 台北總所 | F40: 台北市信義區松仁路100號20樓 | G40: 台北市信義區松仁路100號20樓 | I40: 110/06/09 | J40: 全聯會一字第1100232 | K40: 北市 | L40: 110/06/09 | M40: 4337 | N40: 2026-06-05 | O40: https://www.roccpa.org.tw/member_search/more?id=1B0BB095-AB84-4022-B1AE-26C30A0FF6F7
...

Sheet Deloitte 勤業眾信
A1: 序號 | B1: 事務所名稱 | C1: 國際品牌 | D1: 會計師姓名 | E1: 所屬分所 | F1: 辦公室地址 | G1: 主事務所地址 | H1: 分事務所地址 | I1: 執業登記日期 | J1: 執業登記文號 | K1: 所屬公會 | L1: 入會日期 | M1: 會籍編號 | N1: 資料最後更新日 | O1: 明細連結
A2: 1 | B2: 勤業眾信聯合會計師事務所 | C2: Deloitte 勤業眾信 | D2: 侯玉燡 | E2: 台北總所 | F2: 台北市信義區松仁路100號20樓 | G2: 台北市信義區松仁路100號20樓 | I2: 110/06/09 | J2: 全聯會一字第1100233 | K2: 北市 | L2: 110/06/09 | M2: 4338 | N2: 2026-06-05 | O2: https://www.roccpa.org.tw/member_search/more?id=3005F4E1-61C5-4100-8FF0-5BF2F667E759
A3: 2 | B3: 勤業眾信聯合會計師事務所 | C3: Deloitte 勤業眾信 | D3: 劉力維 | E3: 台北總所 | F3: 台北市信義區松仁路100號20樓 | G3: 台北市信義區松仁路100號20樓 | I3: 111/06/10 | J3: 全聯會一字第1110221 | K3: 北市 | L3: 111/06/10 | M3: 4433 | N3: 2026-06-05 | O3: https://www.roccpa.org.tw/member_search/more?id=6423F685-3F47-4E0E-A3B1-8DCE4666C896
A4: 3 | B4: 勤業眾信聯合會計師事務所 | C4: Deloitte 勤業眾信 | D4: 劉建良 | E4: 台北總所 | F4: 台北市信義區松仁路100號20樓 | G4: 台北市信義區松仁路100號20樓 | I4: 100/05/25 | J4: 全聯會一字第1000207 | K4: 北市 | L4: 100/06/07 | M4: 3354 | N4: 2026-06-05 | O4: https://www.roccpa.org.tw/member_search/more?id=80DA8D03-FCFC-42D8-A83E-38EA6AF532F3
A5: 4 | B5: 勤業眾信聯合會計師事務所 | C5: Deloitte 勤業眾信 | D5: 劉怡青 | E5: 台北總所 | F5: 台北市信義區松仁路100號20樓 | G5: 台北市信義區松仁路100號20樓 | I5: 110/06/09 | J5: 全聯會一字第1100225 | K5: 北市 | L5: 110/06/09 | M5: 4330 | N5: 2026-06-05 | O5: https://www.roccpa.org.tw/member_search/more?id=D91CD5AA-C9AA-4CD0-86EF-DAA5002E83E3
A6: 5 | B6: 勤業眾信聯合會計師事務所 | C6: Deloitte 勤業眾信 | D6: 劉振宇 | E6: 台北總所 | F6: 台北市信義區松仁路100號20樓 | G6: 台北市信義區松仁路100號20樓 | I6: 115/06/15 | J6: 全聯會一字第1150000289號 | K6: 北市 | L6: 115/06/15 | M6: 4896 | N6: 2026-06-23 | O6: https://www.roccpa.org.tw/member_search/more?id=f982591700b54d4b89e36c33ea8fc556
A7: 6 | B7: 勤業眾信聯合會計師事務所 | C7: Deloitte 勤業眾信 | D7: 劉明賢 | E7: 台北總所 | F7: 台北市信義區松仁路100號20樓 | G7: 台北市信義區松仁路100號20樓 | I7: 110/06/09 | J7: 全聯會一字第1100227 | K7: 北市 | L7: 110/06/09 | M7: 4332 | N7: 2026-06-05 | O7: https://www.roccpa.org.tw/member_search/more?id=DC8924EE-20A9-41B4-9C6B-8A49FE225275
A8: 7 | B8: 勤業眾信聯合會計師事務所 | C8: Deloitte 勤業眾信 | D8: 劉書琳 | E8: 台北總所 | F8: 台北市信義區松仁路100號20樓 | G8: 台北市信義區松仁路100號20樓 | I8: 105/06/01 | J8: 全聯會一字第1050250 | K8: 北市 | L8: 105/06/13 | M8: 3937 | N8: 2026-06-05 | O8: https://www.roccpa.org.tw/member_search/more?id=D11D583E-46D4-4239-993F-6658FF47F152
A9: 8 | B9: 勤業眾信聯合會計師事務所 | C9: Deloitte 勤業眾信 | D9: 劉紋伶 | E9: 台北總所 | F9: 台北市信義區松仁路100號20樓 | G9: 台北市信義區松仁路100號20樓 | I9: 113/06/19 | J9: 全聯會一字第1130000278號 | K9: 北市 | L9: 113/06/19 | M9: 4635 | N9: 2026-06-05 | O9: https://www.roccpa.org.tw/member_search/more?id=ABC7DC62-E5AF-4C2F-ACE1-9D39DB9D0037
A10: 9 | B10: 勤業眾信聯合會計師事務所 | C10: Deloitte 勤業眾信 | D10: 劉紋廷 | E10: 台北總所 | F10: 台北市信義區松仁路100號20樓 | G10: 台北市信義區松仁路100號20樓 | I10: 115/06/15 | J10: 全聯會一字第1150000284號 | K10: 北市 | L10: 115/06/15 | M10: 4901 | N10: 2026-06-23 | O10: https://www.roccpa.org.tw/member_search/more?id=827ae8718493401f9576d5ac9eb5be76
A11: 10 | B11: 勤業眾信聯合會計師事務所 | C11: Deloitte 勤業眾信 | D11: 吳世宗 | E11: 台北總所 | F11: 台北市信義區松仁路100號20樓 | G11: 台北市信義區松仁路100號20樓 | I11: 101/06/04 | J11: 全聯會一字第1010178 | K11: 北市 | L11: 101/06/14 | M11: 3470 | N11: 2026-06-05 | O11: https://www.roccpa.org.tw/member_search/more?id=4BE1AABB-8682-4922-95B3-2FEEBBB5A0DD
A12: 11 | B12: 勤業眾信聯合會計師事務所 | C12: Deloitte 勤業眾信 | D12: 吳怡君 | E12: 台北總所 | F12: 台北市信義區松仁路100號20樓 | G12: 台北市信義區松仁路100號20樓 | K12: 北市 | L12: 093/06/10 | M12: 2661 | N12: 2026-06-05 | O12: https://www.roccpa.org.tw/member_search/more?id=0DC99E99-351F-4F1D-BAED-551C3F32F43D
A13: 12 | B13: 勤業眾信聯合會計師事務所 | C13: Deloitte 勤業眾信 | D13: 吳恪昌 | E13: 台北總所 | F13: 台北市信義區松仁路100號20樓 | G13: 台北市信義區松仁路100號20樓 | I13: 100/05/25 | J13: 全聯會一字第1000210 | K13: 北市 | L13: 100/06/07 | M13: 3357 | N13: 2026-06-05 | O13: https://www.roccpa.org.tw/member_search/more?id=F4BF39AB-F306-4487-AFFC-66B1626B79E4
A14: 13 | B14: 勤業眾信聯合會計師事務所 | C14: Deloitte 勤業眾信 | D14: 吳美慧 | E14: 台北總所 | F14: 台北市信義區松仁路100號20樓 | G14: 台北市信義區松仁路100號20樓 | K14: 北市 | L14: 089/11/13 | M14: 2301 | N14: 2026-06-05 | O14: https://www.roccpa.org.tw/member_search/more?id=E1B90370-7D87-474A-9A11-D7F24C193C45
A15: 14 | B15: 勤業眾信聯合會計師事務所 | C15: Deloitte 勤業眾信 | D15: 吳鈞麟 | E15: 台北總所 | F15: 台北市信義區松仁路100號20樓 | G15: 台北市信義區松仁路100號20樓 | I15: 113/06/19 | J15: 全聯會一字第1130000280號 | K15: 北市 | L15: 113/06/19 | M15: 4637 | N15: 2026-06-05 | O15: https://www.roccpa.org.tw/member_search/more?id=6BB7B9CF-C767-45A3-B123-8BD038D8916E
A16: 15 | B16: 勤業眾信聯合會計師事務所 | C16: Deloitte 勤業眾信 | D16: 呂宜真 | E16: 台北總所 | F16: 台北市信義區松仁路100號20樓 | G16: 台北市信義區松仁路100號20樓 | I16: 108/06/12 | J16: 全聯會一字第1080207 | K16: 北市 | L16: 108/06/12 | M16: 4171 | N16: 2026-06-05 | O16: https://www.roccpa.org.tw/member_search/more?id=F1F0537D-0184-4092-A7C1-E45D63985B2D
A17: 16 | B17: 勤業眾信聯合會計師事務所 | C17: Deloitte 勤業眾信 | D17: 呂相瑩 | E17: 台北總所 | F17: 台北市信義區松仁路100號20樓 | G17: 台北市信義區松仁路100號20樓 | I17: 112/06/08 | J17: 全聯會一字第1120224 | K17: 北市 | L17: 112/06/08 | M17: 4530 | N17: 2026-06-05 | O17: https://www.roccpa.org.tw/member_search/more?id=50490783-E4EC-4921-932A-A645450346E7
A18: 17 | B18: 勤業眾信聯合會計師事務所 | C18: Deloitte 勤業眾信 | D18: 周仕杰 | E18: 台北總所 | F18: 台北市信義區松仁路100號20樓 | G18: 台北市信義區松仁路100號20樓 | I18: 111/06/10 | J18: 全聯會一字第1110217 | K18: 北市 | L18: 111/06/10 | M18: 4429 | N18: 2026-06-05 | O18: https://www.roccpa.org.tw/member_search/more?id=BB7E2A76-0446-4D87-A31D-0535B4848099
A19: 18 | B19: 勤業眾信聯合會計師事務所 | C19: Deloitte 勤業眾信 | D19: 周以隆 | E19: 台北總所 | F19: 台北市信義區松仁路100號20樓 | G19: 台北市信義區松仁路100號20樓 | K19: 北市 | L19: 093/06/10 | M19: 2654 | N19: 2026-06-05 | O19: https://www.roccpa.org.tw/member_search/more?id=BD0A1037-DB4C-436E-95E7-55F395ABBD68
A20: 19 | B20: 勤業眾信聯合會計師事務所 | C20: Deloitte 勤業眾信 | D20: 周正國 | E20: 台北總所 | F20: 台北市信義區松仁路100號20樓 | G20: 台北市信義區松仁路100號20樓 | I20: 115/06/15 | J20: 全聯會一字第1150000285號 | K20: 北市 | L20: 115/06/15 | M20: 4892 | N20: 2026-06-23 | O20: https://www.roccpa.org.tw/member_search/more?id=848f6c9fd2984866a3adab8e1355f8c1
A21: 20 | B21: 勤業眾信聯合會計師事務所 | C21: Deloitte 勤業眾信 | D21: 姚勝雄 | E21: 台北總所 | F21: 台北市信義區松仁路100號20樓 | G21: 台北市信義區松仁路100號20樓 | I21: 101/06/04 | J21: 全聯會一字第1010179 | K21: 北市 | L21: 101/06/14 | M21: 3471 | N21: 2026-06-05 | O21: https://www.roccpa.org.tw/member_search/more?id=A622E5B3-327A-42A0-891F-354E8A10874F
A22: 21 | B22: 勤業眾信聯合會計師事務所 | C22: Deloitte 勤業眾信 | D22: 婁朧允 | E22: 台北總所 | F22: 台北市信義區松仁路100號20樓 | G22: 台北市信義區松仁路100號20樓 | I22: 113/06/19 | J22: 全聯會一字第1130000285號 | K22: 北市 | L22: 113/06/19 | M22: 4642 | N22: 2026-06-05 | O22: https://www.roccpa.org.tw/member_search/more?id=9B7805BC-76BC-4F99-8A1A-5368B4B223B2
A23: 22 | B23: 勤業眾信聯合會計師事務所 | C23: Deloitte 勤業眾信 | D23: 尤志峰 | E23: 台北總所 | F23: 台北市信義區松仁路100號20樓 | G23: 台北市信義區松仁路100號20樓 | I23: 114/06/18 | J23: 全聯會一字第1140000240號 | K23: 北市 | L23: 114/06/18 | M23: 4724 | N23: 2026-06-05 | O23: https://www.roccpa.org.tw/member_search/more?id=92D0AF05-9E8B-4FF9-9AD9-64F0108ABC8A
A24: 23 | B24: 勤業眾信聯合會計師事務所 | C24: Deloitte 勤業眾信 | D24: 尤盟貴 | E24: 台北總所 | F24: 台北市信義區松仁路100號20樓 | G24: 台北市信義區松仁路100號20樓 | I24: 113/09/02 | J24: 全聯會一字第1130000400號 | K24: 北市 | L24: 113/09/02 | M24: 4661 | N24: 2026-06-05 | O24: https://www.roccpa.org.tw/member_search/more?id=D7283C06-29A6-4DE9-BD2A-C2654DC37AD2
A25: 24 | B25: 勤業眾信聯合會計師事務所 | C25: Deloitte 勤業眾信 | D25: 康育榮 | E25: 台北總所 | F25: 台北市信義區松仁路100號20樓 | G25: 台北市信義區松仁路100號20樓 | I25: 115/06/15 | J25: 全聯會一字第1150000290號 | K25: 北市 | L25: 115/06/15 | M25: 4897 | N25: 2026-06-23 | O25: https://www.roccpa.org.tw/member_search/more?id=ee3432266cbd4647b4c8ae07e532fd4c
A26: 25 | B26: 勤業眾信聯合會計師事務所 | C26: Deloitte 勤業眾信 | D26: 廖哲莉 | E26: 台北總所 | F26: 台北市信義區松仁路100號20樓 | G26: 台北市信義區松仁路100號20樓 | K26: 北市 | L26: 089/11/13 | M26: 2298 | N26: 2026-06-05 | O26: https://www.roccpa.org.tw/member_search/more?id=68424988-47BA-499B-8D89-682EE399427A
A27: 26 | B27: 勤業眾信聯合會計師事務所 | C27: Deloitte 勤業眾信 | D27: 廖婉怡 | E27: 台北總所 | F27: 台北市信義區松仁路100號20樓 | G27: 台北市信義區松仁路100號20樓 | I27: 101/06/04 | J27: 全聯會一字第1010177 | K27: 北市 | L27: 101/06/14 | M27: 3469 | N27: 2026-06-05 | O27: https://www.roccpa.org.tw/member_search/more?id=248714FA-65F7-4D17-8EBB-9051D13446E7
A28: 27 | B28: 勤業眾信聯合會計師事務所 | C28: Deloitte 勤業眾信 | D28: 廖家琪 | E28: 台北總所 | F28: 台北市信義區松仁路100號20樓 | G28: 台北市信義區松仁路100號20樓 | I28: 109/06/10 | J28: 全聯會一字第1090221 | K28: 北市 | L28: 109/06/10 | M28: 4260 | N28: 2026-06-05 | O28: https://www.roccpa.org.tw/member_search/more?id=0C2E6CB4-6908-48A4-B8AF-62FF19427403
A29: 28 | B29: 勤業眾信聯合會計師事務所 | C29: Deloitte 勤業眾信 | D29: 張哲彥 | E29: 台北總所 | F29: 台北市信義區松仁路100號20樓 | G29: 台北市信義區松仁路100號20樓 | I29: 115/06/15 | J29: 全聯會一字第1150000293號 | K29: 北市 | L29: 115/06/15 | M29: 4900 | N29: 2026-06-23 | O29: https://www.roccpa.org.tw/member_search/more?id=244567f33ca0441188fcb0095e10c1b5
A30: 29 | B30: 勤業眾信聯合會計師事務所 | C30: Deloitte 勤業眾信 | D30: 張嘉銘 | E30: 台北總所 | F30: 台北市信義區松仁路100號20樓 | G30: 台北市信義區松仁路100號20樓 | I30: 114/06/18 | J30: 全聯會一字第1140000241號 | K30: 北市 | L30: 114/06/18 | M30: 4725 | N30: 2026-06-05 | O30: https://www.roccpa.org.tw/member_search/more?id=B66CD394-A7E3-44D9-AEEF-5397956F2629
A31: 30 | B31: 勤業眾信聯合會計師事務所 | C31: Deloitte 勤業眾信 | D31: 張宗銘 | E31: 台北總所 | F31: 台北市信義區松仁路100號20樓 | G31: 台北市信義區松仁路100號20樓 | I31: 099/05/25 | J31: 全聯會一字第09900258 | K31: 北市 | L31: 099/06/04 | M31: 3231 | N31: 2026-06-05 | O31: https://www.roccpa.org.tw/member_search/more?id=CAA6F87C-AD39-469D-9486-D6863E4F543E
A32: 31 | B32: 勤業眾信聯合會計師事務所 | C32: Deloitte 勤業眾信 | D32: 張正修 | E32: 台北總所 | F32: 台北市信義區松仁路100號20樓 | G32: 台北市信義區松仁路100號20樓 | I32: 112/06/08 | J32: 全聯會一字第1120220 | K32: 北市 | L32: 112/06/08 | M32: 4526 | N32: 2026-06-05 | O32: https://www.roccpa.org.tw/member_search/more?id=99645D90-9683-487D-84D5-B799C9A274E2
A33: 32 | B33: 勤業眾信聯合會計師事務所 | C33: Deloitte 勤業眾信 | D33: 張淳儀 | E33: 台北總所 | F33: 台北市信義區松仁路100號20樓 | G33: 台北市信義區松仁路100號20樓 | K33: 北市 | L33: 088/01/29 | M33: 2129 | N33: 2026-06-05 | O33: https://www.roccpa.org.tw/member_search/more?id=633F0845-4E38-4090-AC51-B1EFB13AA945
A34: 33 | B34: 勤業眾信聯合會計師事務所 | C34: Deloitte 勤業眾信 | D34: 張瑞峰 | E34: 台北總所 | F34: 台北市信義區松仁路100號20樓 | G34: 台北市信義區松仁路100號20樓 | I34: 109/06/10 | J34: 全聯會一字第1090214 | K34: 北市 | L34: 109/06/10 | M34: 4253 | N34: 2026-06-05 | O34: https://www.roccpa.org.tw/member_search/more?id=F0292D2E-E20E-431F-BA8A-5077AD9E089B
A35: 34 | B35: 勤業眾信聯合會計師事務所 | C35: Deloitte 勤業眾信 | D35: 張美卿 | E35: 台北總所 | F35: 台北市信義區松仁路100號20樓 | G35: 台北市信義區松仁路100號20樓 | I35: 115/06/15 | J35: 全聯會一字第1150000287號 | K35: 北市 | L35: 115/06/15 | M35: 4894 | N35: 2026-06-23 | O35: https://www.roccpa.org.tw/member_search/more?id=a778492fdcbf4b7596fd9113b85e0c46
A36: 35 | B36: 勤業眾信聯合會計師事務所 | C36: Deloitte 勤業眾信 | D36: 張耿禧 | E36: 台北總所 | F36: 台北市信義區松仁路100號20樓 | G36: 台北市信義區松仁路100號20樓 | K36: 北市 | L36: 090/01/10 | M36: 2333 | N36: 2026-06-05 | O36: https://www.roccpa.org.tw/member_search/more?id=CFDB2A00-A1C4-432F-8693-4343FC0E35F0
A37: 36 | B37: 勤業眾信聯合會計師事務所 | C37: Deloitte 勤業眾信 | D37: 張至誼 | E37: 台北總所 | F37: 台北市信義區松仁路100號20樓 | G37: 台北市信義區松仁路100號20樓 | I37: 109/03/02 | J37: 全聯會一字第1090088 | K37: 北市 | L37: 109/03/02 | M37: 4227 | N37: 2026-06-05 | O37: https://www.roccpa.org.tw/member_search/more?id=2E125208-F858-4843-8CAD-199D8C7C8927
A38: 37 | B38: 勤業眾信聯合會計師事務所 | C38: Deloitte 勤業眾信 | D38: 張雅涵 | E38: 台北總所 | F38: 台北市信義區松仁路100號20樓 | G38: 台北市信義區松仁路100號20樓 | I38: 115/06/15 | J38: 全聯會一字第1150000286號 | K38: 北市 | L38: 115/06/15 | M38: 4893 | N38: 2026-06-23 | O38: https://www.roccpa.org.tw/member_search/more?id=5c684f9c694145659b6a6faa211ca641
A39: 38 | B39: 勤業眾信聯合會計師事務所 | C39: Deloitte 勤業眾信 | D39: 張青霞 | E39: 台北總所 | F39: 台北市信義區松仁路100號20樓 | G39: 台北市信義區松仁路100號20樓 | I39: 109/06/10 | J39: 全聯會一字第1090212 | K39: 北市 | L39: 109/06/10 | M39: 4251 | N39: 2026-06-05 | O39: https://www.roccpa.org.tw/member_search/more?id=36536DF6-1647-428C-A2C4-830E777C6DFE
A40: 39 | B40: 勤業眾信聯合會計師事務所 | C40: Deloitte 勤業眾信 | D40: 張麗君 | E40: 台北總所 | F40: 台北市信義區松仁路100號20樓 | G40: 台北市信義區松仁路100號20樓 | I40: 110/06/09 | J40: 全聯會一字第1100232 | K40: 北市 | L40: 110/06/09 | M40: 4337 | N40: 2026-06-05 | O40: https://www.roccpa.org.tw/member_search/more?id=1B0BB095-AB84-4022-B1AE-26C30A0FF6F7
...

Sheet PwC 資誠
A1: 序號 | B1: 事務所名稱 | C1: 國際品牌 | D1: 會計師姓名 | E1: 所屬分所 | F1: 辦公室地址 | G1: 主事務所地址 | H1: 分事務所地址 | I1: 執業登記日期 | J1: 執業登記文號 | K1: 所屬公會 | L1: 入會日期 | M1: 會籍編號 | N1: 資料最後更新日 | O1: 明細連結
A2: 1 | B2: 資誠聯合會計師事務所 | C2: PwC 資誠 | D2: 于智帆 | E2: 台北總所 | F2: 台北市信義區基隆路一段333號27樓 | G2: 台北市信義區基隆路一段333號27樓 | I2: 111/07/01 | J2: 全聯會一字第1110258 | K2: 北市 | L2: 111/07/01 | M2: 4448 | N2: 2026-06-05 | O2: https://www.roccpa.org.tw/member_search/more?id=ADD9FA2F-90B1-4F0F-A67E-230F0A2C4CB4
A3: 2 | B3: 資誠聯合會計師事務所 | C3: PwC 資誠 | D3: 余正富 | E3: 台北總所 | F3: 台北市信義區基隆路一段333號27樓 | G3: 台北市信義區基隆路一段333號27樓 | I3: 113/07/01 | J3: 全聯會一字第1130000308號 | K3: 北市 | L3: 113/07/01 | M3: 4651 | N3: 2026-06-05 | O3: https://www.roccpa.org.tw/member_search/more?id=A0D371E4-5BA4-4FC7-B010-A6A839F706E3
A4: 3 | B4: 資誠聯合會計師事務所 | C4: PwC 資誠 | D4: 劉國佑 | E4: 台北總所 | F4: 台北市信義區基隆路一段333號27樓 | G4: 台北市信義區基隆路一段333號27樓 | K4: 北市 | L4: 094/08/19 | M4: 2777 | N4: 2026-06-05 | O4: https://www.roccpa.org.tw/member_search/more?id=C64B0BBB-A1D8-485C-828A-ED029C4C5247
A5: 4 | B5: 資誠聯合會計師事務所 | C5: PwC 資誠 | D5: 劉欣萍 | E5: 台北總所 | F5: 台北市信義區基隆路一段333號27樓 | G5: 台北市信義區基隆路一段333號27樓 | I5: 107/06/01 | J5: 全聯會一字第1070229 | K5: 北市 | L5: 107/06/01 | M5: 4100 | N5: 2026-06-05 | O5: https://www.roccpa.org.tw/member_search/more?id=AEA8C81F-46E2-46D2-A6BB-EB4D960956D2
A6: 5 | B6: 資誠聯合會計師事務所 | C6: PwC 資誠 | D6: 劉穎勳 | E6: 台北總所 | F6: 台北市信義區基隆路一段333號27樓 | G6: 台北市信義區基隆路一段333號27樓 | I6: 104/07/01 | J6: 全聯會一字第1040197 | K6: 高市 | L6: 104/07/06 | M6: 966 | N6: 2026-06-05 | O6: https://www.roccpa.org.tw/member_search/more?id=5E79CC7F-DE21-471F-BDBF-BDF2B2750F58
A7: 6 | B7: 資誠聯合會計師事務所 | C7: PwC 資誠 | D7: 吳仁杰 | E7: 台北總所 | F7: 台北市信義區基隆路一段333號27樓 | G7: 台北市信義區基隆路一段333號27樓 | I7: 112/06/15 | J7: 全聯會一字第1120234 | K7: 北市 | L7: 112/06/15 | M7: 4537 | N7: 2026-06-05 | O7: https://www.roccpa.org.tw/member_search/more?id=0CEEB349-8A0E-41CF-8B76-32932241B021
A8: 7 | B8: 資誠聯合會計師事務所 | C8: PwC 資誠 | D8: 吳偉臺 | E8: 台北總所 | F8: 台北市信義區基隆路一段333號27樓 | G8: 台北市信義區基隆路一段333號27樓 | I8: 106/01/09 | J8: 全聯會一字第1060038 | K8: 北市 | L8: 106/01/18 | M8: 3987 | N8: 2026-06-05 | O8: https://www.roccpa.org.tw/member_search/more?id=1CE1159C-AA51-4AD4-A020-AD1B88ED71F0
A9: 8 | B9: 資誠聯合會計師事務所 | C9: PwC 資誠 | D9: 吳尚燉 | E9: 台北總所 | F9: 台北市信義區基隆路一段333號27樓 | G9: 台北市信義區基隆路一段333號27樓 | I9: 110/06/15 | J9: 全聯會一字第1100238 | K9: 北市 | L9: 110/06/15 | M9: 4341 | N9: 2026-06-05 | O9: https://www.roccpa.org.tw/member_search/more?id=57044CB0-CA29-4D3B-8EB9-911576C9C3BA
A10: 9 | B10: 資誠聯合會計師事務所 | C10: PwC 資誠 | D10: 吳建志 | E10: 台北總所 | F10: 台北市信義區基隆路一段333號27樓 | G10: 台北市信義區基隆路一段333號27樓 | I10: 103/06/11 | J10: 全聯會一字第1030223 | K10: 高市 | L10: 103/06/25 | M10: 919 | N10: 2026-06-05 | O10: https://www.roccpa.org.tw/member_search/more?id=ECB5C458-9611-45A5-B206-B35D6A3ED3B3
A11: 10 | B11: 資誠聯合會計師事務所 | C11: PwC 資誠 | D11: 周筱姿 | E11: 台北總所 | F11: 台北市信義區基隆路一段333號27樓 | G11: 台北市信義區基隆路一段333號27樓 | K11: 北市 | L11: 085/09/17 | M11: 1833 | N11: 2026-06-05 | O11: https://www.roccpa.org.tw/member_search/more?id=14B33E5F-0C83-4FD6-95CA-8DD19B150B2C
A12: 11 | B12: 資誠聯合會計師事務所 | C12: PwC 資誠 | D12: 周莉莉 | E12: 台北總所 | F12: 台北市信義區基隆路一段333號27樓 | G12: 台北市信義區基隆路一段333號27樓 | I12: 104/07/01 | J12: 全聯會一字第1040196 | K12: 北市 | L12: 104/07/07 | M12: 3843 | N12: 2026-06-05 | O12: https://www.roccpa.org.tw/member_search/more?id=420783DE-5DCD-4324-8BC1-56CD315C9E66
A13: 12 | B13: 資誠聯合會計師事務所 | C13: PwC 資誠 | D13: 奧田健士 | E13: 台北總所 | F13: 台北市信義區基隆路一段333號27樓 | G13: 台北市信義區基隆路一段333號27樓 | I13: 110/02/01 | J13: 全聯會一字第1100055 | K13: 北市 | L13: 110/02/01 | M13: 4301 | N13: 2026-06-05 | O13: https://www.roccpa.org.tw/member_search/more?id=5BD4D921-884E-4340-A067-3ED6FF12DD85
A14: 13 | B14: 資誠聯合會計師事務所 | C14: PwC 資誠 | D14: 廖容翎 | E14: 台北總所 | F14: 台北市信義區基隆路一段333號27樓 | G14: 台北市信義區基隆路一段333號27樓 | I14: 112/06/15 | J14: 全聯會一字第1120236 | K14: 北市 | L14: 112/06/15 | M14: 4539 | N14: 2026-06-05 | O14: https://www.roccpa.org.tw/member_search/more?id=4615F950-C870-4BFE-B272-B3DDACA55B41
A15: 14 | B15: 資誠聯合會計師事務所 | C15: PwC 資誠 | D15: 廖福銘 | E15: 台北總所 | F15: 台北市信義區基隆路一段333號27樓 | G15: 台北市信義區基隆路一段333號27樓 | I15: 109/07/01 | J15: 全聯會一字第1090240 | K15: 北市 | L15: 109/07/01 | M15: 4263 | N15: 2026-06-05 | O15: https://www.roccpa.org.tw/member_search/more?id=BB108312-90E1-46B0-9831-FAB84B5825DE
A16: 15 | B16: 資誠聯合會計師事務所 | C16: PwC 資誠 | D16: 廖阿甚 | E16: 台北總所 | F16: 台北市信義區基隆路一段333號27樓 | G16: 台北市信義區基隆路一段333號27樓 | I16: 101/03/30 | J16: 全聯會一字第1010109 | K16: 高市 | L16: 101/06/26 | M16: 813 | N16: 2026-06-05 | O16: https://www.roccpa.org.tw/member_search/more?id=F800D243-56A1-4459-9EC3-2514C5740609
A17: 16 | B17: 資誠聯合會計師事務所 | C17: PwC 資誠 | D17: 張凱智 | E17: 台北總所 | F17: 台北市信義區基隆路一段333號27樓 | G17: 台北市信義區基隆路一段333號27樓 | I17: 111/08/01 | J17: 全聯會一字第1110311 | K17: 北市 | L17: 111/08/01 | M17: 4453 | N17: 2026-06-05 | O17: https://www.roccpa.org.tw/member_search/more?id=068B9D16-7683-4756-9F9D-D0D084A9982F
A18: 17 | B18: 資誠聯合會計師事務所 | C18: PwC 資誠 | D18: 張家荃 | E18: 台北總所 | F18: 台北市信義區基隆路一段333號27樓 | G18: 台北市信義區基隆路一段333號27樓 | I18: 114/07/01 | J18: 全聯會一字第1140000268號 | K18: 北市 | L18: 114/07/01 | M18: 4737 | N18: 2026-06-05 | O18: https://www.roccpa.org.tw/member_search/more?id=9AD3652A-72F1-4586-ADD5-845B0D902425
A19: 18 | B19: 資誠聯合會計師事務所 | C19: PwC 資誠 | D19: 張志安 | E19: 台北總所 | F19: 台北市信義區基隆路一段333號27樓 | G19: 台北市信義區基隆路一段333號27樓 | K19: 中市 | L19: 100/12/29 | M19: 288 | N19: 2026-06-05 | O19: https://www.roccpa.org.tw/member_search/more?id=332472A1-B02E-43F7-BA31-03FDD54569D4
A20: 19 | B20: 資誠聯合會計師事務所 | C20: PwC 資誠 | D20: 張淑瓊 | E20: 台北總所 | F20: 台北市信義區基隆路一段333號27樓 | G20: 台北市信義區基隆路一段333號27樓 | I20: 099/07/09 | J20: 全聯會一字第09900322 | K20: 北市 | L20: 099/07/19 | M20: 3245 | N20: 2026-06-05 | O20: https://www.roccpa.org.tw/member_search/more?id=EE7FC356-E1A2-4B7C-9458-7AEDD7535A7E
A21: 20 | B21: 資誠聯合會計師事務所 | C21: PwC 資誠 | D21: 張珍綺 | E21: 台北總所 | F21: 台北市信義區基隆路一段333號27樓 | G21: 台北市信義區基隆路一段333號27樓 | I21: 115/07/01 | J21: 全聯會一字第1150000324號 | K21: 北市 | L21: 115/07/01 | M21: 4912 | N21: 2026-07-06 | O21: https://www.roccpa.org.tw/member_search/more?id=dca64c68795c4e8999caf2a3d6ea4688
A22: 21 | B22: 資誠聯合會計師事務所 | C22: PwC 資誠 | D22: 張瑞婷 | E22: 台北總所 | F22: 台北市信義區基隆路一段333號27樓 | G22: 台北市信義區基隆路一段333號27樓 | I22: 107/06/01 | J22: 全聯會一字第1070227 | K22: 北市 | L22: 107/06/01 | M22: 4098 | N22: 2026-06-05 | O22: https://www.roccpa.org.tw/member_search/more?id=73D7038F-FAD5-4EA3-873E-53009AB2756A
A23: 22 | B23: 資誠聯合會計師事務所 | C23: PwC 資誠 | D23: 徐丞毅 | E23: 台北總所 | F23: 台北市信義區基隆路一段333號27樓 | G23: 台北市信義區基隆路一段333號27樓 | I23: 109/07/01 | J23: 全聯會一字第1090239 | K23: 北市 | L23: 109/07/01 | M23: 4262 | N23: 2026-06-05 | O23: https://www.roccpa.org.tw/member_search/more?id=74839B88-1FD8-4ADA-BA5A-5957D9785751
A24: 23 | B24: 資誠聯合會計師事務所 | C24: PwC 資誠 | D24: 徐明釧 | E24: 台北總所 | F24: 台北市信義區基隆路一段333號27樓 | G24: 台北市信義區基隆路一段333號27樓 | I24: 105/06/22 | J24: 全聯會一字第1050272 | K24: 北市 | L24: 105/07/21 | M24: 3944 | N24: 2026-06-05 | O24: https://www.roccpa.org.tw/member_search/more?id=D86185B7-A5D2-427B-B7F0-B769AB4A9E1E
A25: 24 | B25: 資誠聯合會計師事務所 | C25: PwC 資誠 | D25: 徐潔如 | E25: 台北總所 | F25: 台北市信義區基隆路一段333號27樓 | G25: 台北市信義區基隆路一段333號27樓 | I25: 110/06/15 | J25: 全聯會一字第1100239 | K25: 北市 | L25: 110/06/15 | M25: 4342 | N25: 2026-06-05 | O25: https://www.roccpa.org.tw/member_search/more?id=27C4F48A-33B6-417F-9A21-E926975A5473
A26: 25 | B26: 資誠聯合會計師事務所 | C26: PwC 資誠 | D26: 徐聖忠 | E26: 台北總所 | F26: 台北市信義區基隆路一段333號27樓 | G26: 台北市信義區基隆路一段333號27樓 | I26: 101/06/27 | J26: 全聯會一字第1010196 | K26: 北市 | L26: 101/07/06 | M26: 3477 | N26: 2026-06-05 | O26: https://www.roccpa.org.tw/member_search/more?id=66C7DBB9-2CAB-4DFC-A367-84EC067254E9
A27: 26 | B27: 資誠聯合會計師事務所 | C27: PwC 資誠 | D27: 徐麗珍 | E27: 台北總所 | F27: 台北市信義區基隆路一段333號27樓 | G27: 台北市信義區基隆路一段333號27樓 | K27: 北市 | L27: 094/08/19 | M27: 2778 | N27: 2026-06-05 | O27: https://www.roccpa.org.tw/member_search/more?id=DAB542FE-3AB5-4948-AD71-F0D241EC1165
A28: 27 | B28: 資誠聯合會計師事務所 | C28: PwC 資誠 | D28: 支秉鈞 | E28: 台北總所 | F28: 台北市信義區基隆路一段333號27樓 | G28: 台北市信義區基隆路一段333號27樓 | K28: 北市 | L28: 087/11/02 | M28: 2087 | N28: 2026-06-05 | O28: https://www.roccpa.org.tw/member_search/more?id=C3C4EFCE-A0AD-4229-BE5F-29E997D6E606
A29: 28 | B29: 資誠聯合會計師事務所 | C29: PwC 資誠 | D29: 文雅芳 | E29: 台北總所 | F29: 台北市信義區基隆路一段333號27樓 | G29: 台北市信義區基隆路一段333號27樓 | I29: 110/06/15 | J29: 全聯會一字第1100240 | K29: 北市 | L29: 110/06/15 | M29: 4343 | N29: 2026-06-05 | O29: https://www.roccpa.org.tw/member_search/more?id=DE57BFF4-7164-4A93-A425-1CE132EE8353
A30: 29 | B30: 資誠聯合會計師事務所 | C30: PwC 資誠 | D30: 施敏智 | E30: 台北總所 | F30: 台北市信義區基隆路一段333號27樓 | G30: 台北市信義區基隆路一段333號27樓 | I30: 110/07/19 | J30: 全聯會一字第1100285 | K30: 北市 | L30: 110/07/19 | M30: 4359 | N30: 2026-06-05 | O30: https://www.roccpa.org.tw/member_search/more?id=32F16146-FA80-4510-9F4D-5C6B952F3F91
A31: 30 | B31: 資誠聯合會計師事務所 | C31: PwC 資誠 | D31: 曾博昇 | E31: 台北總所 | F31: 台北市信義區基隆路一段333號27樓 | G31: 台北市信義區基隆路一段333號27樓 | I31: 105/06/22 | J31: 全聯會一字第1050274 | K31: 北市 | L31: 105/07/21 | M31: 3946 | N31: 2026-06-05 | O31: https://www.roccpa.org.tw/member_search/more?id=85A5842F-F961-46B2-A4A6-1B5EBEF3DDD0
A32: 31 | B32: 資誠聯合會計師事務所 | C32: PwC 資誠 | D32: 李南漢 | E32: 台北總所 | F32: 台北市信義區基隆路一段333號27樓 | G32: 台北市信義區基隆路一段333號27樓 | I32: 115/07/01 | J32: 全聯會一字第1150000326號 | K32: 北市 | L32: 115/07/01 | M32: 4914 | N32: 2026-07-06 | O32: https://www.roccpa.org.tw/member_search/more?id=581be078a8cc4cf68ba2413c163c548e
A33: 32 | B33: 資誠聯合會計師事務所 | C33: PwC 資誠 | D33: 李宜樺 | E33: 台北總所 | F33: 台北市信義區基隆路一段333號27樓 | G33: 台北市信義區基隆路一段333號27樓 | K33: 北市 | L33: 095/12/01 | M33: 2891 | N33: 2026-06-05 | O33: https://www.roccpa.org.tw/member_search/more?id=96A72699-413F-4ABD-8F4E-8443EFA3A16F
A34: 33 | B34: 資誠聯合會計師事務所 | C34: PwC 資誠 | D34: 李秀玲 | E34: 台北總所 | F34: 台北市信義區基隆路一段333號27樓 | G34: 台北市信義區基隆路一段333號27樓 | K34: 北市 | L34: 088/12/08 | M34: 2228 | N34: 2026-06-05 | O34: https://www.roccpa.org.tw/member_search/more?id=0E0B2E71-6A26-4EEA-9D1F-2CD61AA7ED89
A35: 34 | B35: 資誠聯合會計師事務所 | C35: PwC 資誠 | D35: 林一帆 | E35: 台北總所 | F35: 台北市信義區基隆路一段333號27樓 | G35: 台北市信義區基隆路一段333號27樓 | I35: 103/02/18 | J35: 全聯會一字第1030058 | K35: 北市 | L35: 103/03/03 | M35: 3666 | N35: 2026-06-05 | O35: https://www.roccpa.org.tw/member_search/more?id=0808AA7C-0DBE-49F9-8127-063EA682E918
A36: 35 | B36: 資誠聯合會計師事務所 | C36: PwC 資誠 | D36: 林佳鴻 | E36: 台北總所 | F36: 台北市信義區基隆路一段333號27樓 | G36: 台北市信義區基隆路一段333號27樓 | I36: 108/07/01 | J36: 全聯會一字第1080237 | K36: 北市 | L36: 108/07/01 | M36: 4175 | N36: 2026-06-05 | O36: https://www.roccpa.org.tw/member_search/more?id=B8017374-D404-476F-A063-EB849A2FAEFA
A37: 36 | B37: 資誠聯合會計師事務所 | C37: PwC 資誠 | D37: 林冠宏 | E37: 台北總所 | F37: 台北市信義區基隆路一段333號27樓 | G37: 台北市信義區基隆路一段333號27樓 | I37: 111/07/01 | J37: 全聯會一字第1110256 | K37: 北市 | L37: 111/07/01 | M37: 4446 | N37: 2026-06-05 | O37: https://www.roccpa.org.tw/member_search/more?id=A7966797-EF14-410C-8957-3545736BAAC0
A38: 37 | B38: 資誠聯合會計師事務所 | C38: PwC 資誠 | D38: 林巨峯 | E38: 台北總所 | F38: 台北市信義區基隆路一段333號27樓 | G38: 台北市信義區基隆路一段333號27樓 | I38: 106/06/01 | J38: 全聯會一字第1060208 | K38: 北市 | L38: 106/06/21 | M38: 4023 | N38: 2026-06-05 | O38: https://www.roccpa.org.tw/member_search/more?id=EA99C1C5-7715-4168-A109-F6E67DEA91D0
A39: 38 | B39: 資誠聯合會計師事務所 | C39: PwC 資誠 | D39: 林柏全 | E39: 台北總所 | F39: 台北市信義區基隆路一段333號27樓 | G39: 台北市信義區基隆路一段333號27樓 | I39: 110/06/15 | J39: 全聯會一字第110241 | K39: 北市 | L39: 110/06/15 | M39: 4344 | N39: 2026-06-05 | O39: https://www.roccpa.org.tw/member_search/more?id=48910A65-A944-442D-B8C1-E5B0961BD25B
A40: 39 | B40: 資誠聯合會計師事務所 | C40: PwC 資誠 | D40: 林永智 | E40: 台北總所 | F40: 台北市信義區基隆路一段333號27樓 | G40: 台北市信義區基隆路一段333號27樓 | I40: 105/06/22 | J40: 全聯會一字第1050275 | K40: 北市 | L40: 113/10/16 | M40: 4671 | N40: 2026-06-05 | O40: https://www.roccpa.org.tw/member_search/more?id=94DE7672-E2FE-4CB1-8141-1227BDF01E3C
...

Sheet KPMG 安侯建業
A1: 序號 | B1: 事務所名稱 | C1: 國際品牌 | D1: 會計師姓名 | E1: 所屬分所 | F1: 辦公室地址 | G1: 主事務所地址 | H1: 分事務所地址 | I1: 執業登記日期 | J1: 執業登記文號 | K1: 所屬公會 | L1: 入會日期 | M1: 會籍編號 | N1: 資料最後更新日 | O1: 明細連結
A2: 1 | B2: 安侯建業聯合會計師事務所 | C2: KPMG 安侯建業 | D2: 丁傳倫 | E2: 台北總所 | F2: 台北市信義區信義路五段7號68樓 | G2: 台北市信義區信義路五段7號68樓 | I2: 109/07/06 | J2: 全聯會一字第1090245 | K2: 北市 | L2: 109/07/06 | M2: 4266 | N2: 2026-06-05 | O2: https://www.roccpa.org.tw/member_search/more?id=642B1E83-21FD-475C-9EE6-5DF3BF9A9D20
A3: 2 | B3: 安侯建業聯合會計師事務所 | C3: KPMG 安侯建業 | D3: 丁英泰 | E3: 台北總所 | F3: 台北市信義區信義路五段7號68樓 | G3: 台北市信義區信義路五段7號68樓 | I3: 112/06/13 | J3: 全聯會一字第1120228 | K3: 北市 | L3: 112/06/13 | M3: 4532 | N3: 2026-06-05 | O3: https://www.roccpa.org.tw/member_search/more?id=308A9B30-02D0-46CC-ABBB-5A056AB2BB57
A4: 3 | B4: 安侯建業聯合會計師事務所 | C4: KPMG 安侯建業 | D4: 于紀隆 | E4: 台北總所 | F4: 台北市信義區信義路五段7號68樓 | G4: 台北市信義區信義路五段7號68樓 | K4: 北市 | L4: 090/09/21 | M4: 2393 | N4: 2026-06-05 | O4: https://www.roccpa.org.tw/member_search/more?id=16C39D64-7A70-4121-AB16-3C76D8643D71
A5: 4 | B5: 安侯建業聯合會計師事務所 | C5: KPMG 安侯建業 | D5: 余聖河 | E5: 台北總所 | F5: 台北市信義區信義路五段7號68樓 | G5: 台北市信義區信義路五段7號68樓 | I5: 101/01/19 | J5: 全聯會一字第1010021 | K5: 北市 | L5: 101/02/06 | M5: 3420 | N5: 2026-06-05 | O5: https://www.roccpa.org.tw/member_search/more?id=9FA798CA-9F29-41F1-A34B-00AE0F82EC55
A6: 5 | B6: 安侯建業聯合會計師事務所 | C6: KPMG 安侯建業 | D6: 傅泓文 | E6: 台北總所 | F6: 台北市信義區信義路五段7號68樓 | G6: 台北市信義區信義路五段7號68樓 | I6: 109/01/31 | J6: 全聯會一字第1090040 | K6: 北市 | L6: 109/01/31 | M6: 4216 | N6: 2026-06-05 | O6: https://www.roccpa.org.tw/member_search/more?id=89F78F06-502F-4D77-A9F2-BBA1D42859B8
A7: 6 | B7: 安侯建業聯合會計師事務所 | C7: KPMG 安侯建業 | D7: 劉中惠 | E7: 台北總所 | F7: 台北市信義區信義路五段7號68樓 | G7: 台北市信義區信義路五段7號68樓 | I7: 109/07/06 | J7: 全聯會一字第1090244 | K7: 北市 | L7: 109/07/06 | M7: 4265 | N7: 2026-06-05 | O7: https://www.roccpa.org.tw/member_search/more?id=DFF78DE1-3174-4A2D-98FE-10F16968DC4E
A8: 7 | B8: 安侯建業聯合會計師事務所 | C8: KPMG 安侯建業 | D8: 劉振興 | E8: 台北總所 | F8: 台北市信義區信義路五段7號68樓 | G8: 台北市信義區信義路五段7號68樓 | I8: 114/10/03 | J8: 全聯會一字第1140000490號 | K8: 北市 | L8: 114/10/03 | M8: 4846 | N8: 2026-06-05 | O8: https://www.roccpa.org.tw/member_search/more?id=858CD947-7F36-4FEC-96D9-31D83404C331
A9: 8 | B9: 安侯建業聯合會計師事務所 | C9: KPMG 安侯建業 | D9: 區耀軍 | E9: 台北總所 | F9: 台北市信義區信義路五段7號68樓 | G9: 台北市信義區信義路五段7號68樓 | K9: 北市 | L9: 093/01/05 | M9: 2613 | N9: 2026-06-05 | O9: https://www.roccpa.org.tw/member_search/more?id=1552092C-6E6D-4789-8C3C-7E469B4819A3
A10: 9 | B10: 安侯建業聯合會計師事務所 | C10: KPMG 安侯建業 | D10: 吳仲舜 | E10: 台北總所 | F10: 台北市信義區信義路五段7號68樓 | G10: 台北市信義區信義路五段7號68樓 | I10: 109/01/31 | J10: 全聯會一字第1090041 | K10: 北市 | L10: 109/01/31 | M10: 4217 | N10: 2026-06-05 | O10: https://www.roccpa.org.tw/member_search/more?id=B0D476AC-B902-4AF6-82A7-363985E3DA22
A11: 10 | B11: 安侯建業聯合會計師事務所 | C11: KPMG 安侯建業 | D11: 吳佳翰 | E11: 台北總所 | F11: 台北市信義區信義路五段7號68樓 | G11: 台北市信義區信義路五段7號68樓 | I11: 113/01/15 | J11: 全聯會一字第1130000028號 | K11: 北市 | L11: 113/01/15 | M11: 4591 | N11: 2026-06-05 | O11: https://www.roccpa.org.tw/member_search/more?id=92522745-0A6B-4751-B1CB-8A4395064547
A12: 11 | B12: 安侯建業聯合會計師事務所 | C12: KPMG 安侯建業 | D12: 吳政諺 | E12: 台北總所 | F12: 台北市信義區信義路五段7號68樓 | G12: 台北市信義區信義路五段7號68樓 | I12: 106/10/06 | J12: 全聯會一字第1060358 | K12: 北市 | L12: 106/10/06 | M12: 4044 | N12: 2026-06-05 | O12: https://www.roccpa.org.tw/member_search/more?id=D1F389ED-187E-474C-92E8-FB5254C9F27B
A13: 12 | B13: 安侯建業聯合會計師事務所 | C13: KPMG 安侯建業 | D13: 吳祁達 | E13: 台北總所 | F13: 台北市信義區信義路五段7號68樓 | G13: 台北市信義區信義路五段7號68樓 | I13: 114/10/03 | J13: 全聯會一字第1140000488號 | K13: 北市 | L13: 114/10/03 | M13: 4844 | N13: 2026-06-05 | O13: https://www.roccpa.org.tw/member_search/more?id=ED306F82-CB10-4FF2-9B80-8CF17B04CF90
A14: 13 | B14: 安侯建業聯合會計師事務所 | C14: KPMG 安侯建業 | D14: 吳趙仁 | E14: 台北總所 | F14: 台北市信義區信義路五段7號68樓 | G14: 台北市信義區信義路五段7號68樓 | I14: 107/02/05 | J14: 全聯會一字第1070074 | K14: 北市 | L14: 107/02/05 | M14: 4071 | N14: 2026-06-05 | O14: https://www.roccpa.org.tw/member_search/more?id=DFF7E801-A33C-4F63-B3F9-4941F4CFA7A5
A15: 14 | B15: 安侯建業聯合會計師事務所 | C15: KPMG 安侯建業 | D15: 吳麟 | E15: 台北總所 | F15: 台北市信義區信義路五段7號68樓 | G15: 台北市信義區信義路五段7號68樓 | K15: 北市 | L15: 096/10/01 | M15: 2962 | N15: 2026-06-05 | O15: https://www.roccpa.org.tw/member_search/more?id=735B3B6F-B5B7-487B-A906-E92D0EB9F089
A16: 15 | B16: 安侯建業聯合會計師事務所 | C16: KPMG 安侯建業 | D16: 周寶蓮 | E16: 台北總所 | F16: 台北市信義區信義路五段7號68樓 | G16: 台北市信義區信義路五段7號68樓 | K16: 北市 | L16: 093/05/10 | M16: 2637 | N16: 2026-06-05 | O16: https://www.roccpa.org.tw/member_search/more?id=25B63349-850F-4692-9514-F4DFD01718B3
A17: 16 | B17: 安侯建業聯合會計師事務所 | C17: KPMG 安侯建業 | D17: 唐嘉鍵 | E17: 台北總所 | F17: 台北市信義區信義路五段7號68樓 | G17: 台北市信義區信義路五段7號68樓 | I17: 108/01/14 | J17: 全聯會一字第1080034 | K17: 北市 | L17: 108/01/14 | M17: 4149 | N17: 2026-06-05 | O17: https://www.roccpa.org.tw/member_search/more?id=A47519EC-71B7-4CC1-8C9C-EAF6139EBFCB
A18: 17 | B18: 安侯建業聯合會計師事務所 | C18: KPMG 安侯建業 | D18: 寇惠植 | E18: 台北總所 | F18: 台北市信義區信義路五段7號68樓 | G18: 台北市信義區信義路五段7號68樓 | K18: 北市 | L18: 086/12/17 | M18: 1989 | N18: 2026-06-05 | O18: https://www.roccpa.org.tw/member_search/more?id=DF68C182-06CF-4CCA-8A76-AF9CEB938F3C
A19: 18 | B19: 安侯建業聯合會計師事務所 | C19: KPMG 安侯建業 | D19: 尹元聖 | E19: 台北總所 | F19: 台北市信義區信義路五段7號68樓 | G19: 台北市信義區信義路五段7號68樓 | I19: 105/03/07 | J19: 全聯會一字第1050124 | K19: 北市 | L19: 105/03/16 | M19: 3906 | N19: 2026-06-05 | O19: https://www.roccpa.org.tw/member_search/more?id=40F0714B-E3EE-44B9-BA22-C783C9DFDC30
A20: 19 | B20: 安侯建業聯合會計師事務所 | C20: KPMG 安侯建業 | D20: 張惠貞 | E20: 台北總所 | F20: 台北市信義區信義路五段7號68樓 | G20: 台北市信義區信義路五段7號68樓 | K20: 北市 | L20: 081/11/23 | M20: 1419 | N20: 2026-06-05 | O20: https://www.roccpa.org.tw/member_search/more?id=9037C6F3-8701-4DDC-8778-3C0BA03208AD
A21: 20 | B21: 安侯建業聯合會計師事務所 | C21: KPMG 安侯建業 | D21: 張智揚 | E21: 台北總所 | F21: 台北市信義區信義路五段7號68樓 | G21: 台北市信義區信義路五段7號68樓 | I21: 111/02/07 | J21: 全聯會一字第1110070 | K21: 北市 | L21: 111/02/07 | M21: 4400 | N21: 2026-06-05 | O21: https://www.roccpa.org.tw/member_search/more?id=4CBA9ABF-D35E-4798-9543-8B7E33203BE8
A22: 21 | B22: 安侯建業聯合會計師事務所 | C22: KPMG 安侯建業 | D22: 張淑瑩 | E22: 台北總所 | F22: 台北市信義區信義路五段7號68樓 | G22: 台北市信義區信義路五段7號68樓 | K22: 北市 | L22: 088/09/28 | M22: 2191 | N22: 2026-06-05 | O22: https://www.roccpa.org.tw/member_search/more?id=4B50D5E9-BE98-451B-A9D2-785F03E4B40D
A23: 22 | B23: 安侯建業聯合會計師事務所 | C23: KPMG 安侯建業 | D23: 張純怡 | E23: 台北總所 | F23: 台北市信義區信義路五段7號68樓 | G23: 台北市信義區信義路五段7號68樓 | I23: 105/08/17 | J23: 全聯會一字第1050357 | K23: 北市 | L23: 105/08/22 | M23: 3955 | N23: 2026-06-05 | O23: https://www.roccpa.org.tw/member_search/more?id=DEB62E18-1703-4AD0-AF44-C1A0EEDE96EA
A24: 23 | B24: 安侯建業聯合會計師事務所 | C24: KPMG 安侯建業 | D24: 張維夫 | E24: 台北總所 | F24: 台北市信義區信義路五段7號68樓 | G24: 台北市信義區信義路五段7號68樓 | I24: 100/06/28 | J24: 全聯會一字第1000251 | K24: 北市 | L24: 100/07/06 | M24: 3367 | N24: 2026-06-05 | O24: https://www.roccpa.org.tw/member_search/more?id=D404CC9D-99BE-4A4B-A2B7-689BA4B58F04
A25: 24 | B25: 安侯建業聯合會計師事務所 | C25: KPMG 安侯建業 | D25: 張維欣 | E25: 台北總所 | F25: 台北市信義區信義路五段7號68樓 | G25: 台北市信義區信義路五段7號68樓 | I25: 114/01/13 | J25: 全聯會一字第1140000040號 | K25: 北市 | L25: 114/01/13 | M25: 4696 | N25: 2026-06-05 | O25: https://www.roccpa.org.tw/member_search/more?id=5CE22604-5FDC-4B53-AFFF-3C803D13EA16
A26: 25 | B26: 安侯建業聯合會計師事務所 | C26: KPMG 安侯建業 | D26: 張肇文 | E26: 台北總所 | F26: 台北市信義區信義路五段7號68樓 | G26: 台北市信義區信義路五段7號68樓 | I26: 114/01/13 | J26: 全聯會一字第1140000037號 | K26: 北市 | L26: 114/01/13 | M26: 4693 | N26: 2026-06-05 | O26: https://www.roccpa.org.tw/member_search/more?id=C6785576-4E84-4832-91B5-4BF76B32DC52
A27: 26 | B27: 安侯建業聯合會計師事務所 | C27: KPMG 安侯建業 | D27: 施威銘 | E27: 台北總所 | F27: 台北市信義區信義路五段7號68樓 | G27: 台北市信義區信義路五段7號68樓 | K27: 北市 | L27: 090/03/15 | M27: 2352 | N27: 2026-06-05 | O27: https://www.roccpa.org.tw/member_search/more?id=9FE7A46D-E360-412D-9647-F959798A1F70
A28: 27 | B28: 安侯建業聯合會計師事務所 | C28: KPMG 安侯建業 | D28: 曾國禓 | E28: 台北總所 | F28: 台北市信義區信義路五段7號68樓 | G28: 台北市信義區信義路五段7號68樓 | K28: 北市 | L28: 093/12/16 | M28: 2701 | N28: 2026-06-05 | O28: https://www.roccpa.org.tw/member_search/more?id=D306462A-4EA9-409C-B410-533633DA3B97
A29: 28 | B29: 安侯建業聯合會計師事務所 | C29: KPMG 安侯建業 | D29: 李䄱儀 | E29: 台北總所 | F29: 台北市信義區信義路五段7號68樓 | G29: 台北市信義區信義路五段7號68樓 | I29: 101/01/19 | J29: 全聯會一字第1010020 | K29: 北市 | L29: 101/02/06 | M29: 3419 | N29: 2026-06-05 | O29: https://www.roccpa.org.tw/member_search/more?id=A1A1601F-D000-4EAC-BC9F-AF15E05DBC48
A30: 29 | B30: 安侯建業聯合會計師事務所 | C30: KPMG 安侯建業 | D30: 李慈慧 | E30: 台北總所 | F30: 台北市信義區信義路五段7號68樓 | G30: 台北市信義區信義路五段7號68樓 | K30: 北市 | L30: 085/12/31 | M30: 1888 | N30: 2026-06-05 | O30: https://www.roccpa.org.tw/member_search/more?id=B1E3373C-27A8-49C7-9F2A-1B9441715A61
A31: 30 | B31: 安侯建業聯合會計師事務所 | C31: KPMG 安侯建業 | D31: 李逢暉 | E31: 台北總所 | F31: 台北市信義區信義路五段7號68樓 | G31: 台北市信義區信義路五段7號68樓 | I31: 100/03/14 | J31: 全聯會一字第1000092 | K31: 北市 | L31: 100/03/16 | M31: 3327 | N31: 2026-06-05 | O31: https://www.roccpa.org.tw/member_search/more?id=72DAC401-2071-4F55-8382-DF8FC0B63908
A32: 31 | B32: 安侯建業聯合會計師事務所 | C32: KPMG 安侯建業 | D32: 林佳伶 | E32: 台北總所 | F32: 台北市信義區信義路五段7號68樓 | G32: 台北市信義區信義路五段7號68樓 | I32: 114/10/03 | J32: 全聯會一字第1140000487號 | K32: 北市 | L32: 114/10/03 | M32: 4843 | N32: 2026-06-05 | O32: https://www.roccpa.org.tw/member_search/more?id=0D0EA596-7040-4052-A94F-576A891ADD80
A33: 32 | B33: 安侯建業聯合會計師事務所 | C33: KPMG 安侯建業 | D33: 林倚聰 | E33: 台北總所 | F33: 台北市信義區信義路五段7號68樓 | G33: 台北市信義區信義路五段7號68樓 | I33: 111/06/13 | J33: 全聯會一字第1110225 | K33: 北市 | L33: 111/06/13 | M33: 4437 | N33: 2026-06-05 | O33: https://www.roccpa.org.tw/member_search/more?id=346545FF-726C-4F07-87E1-44675DB8E190
A34: 33 | B34: 安侯建業聯合會計師事務所 | C34: KPMG 安侯建業 | D34: 林君彬 | E34: 台北總所 | F34: 台北市信義區信義路五段7號68樓 | G34: 台北市信義區信義路五段7號68樓 | I34: 114/10/03 | J34: 全聯會一字第1140000489號 | K34: 北市 | L34: 114/10/03 | M34: 4845 | N34: 2026-06-05 | O34: https://www.roccpa.org.tw/member_search/more?id=B059D6B6-143D-4488-A59B-4D06A1230DCA
A35: 34 | B35: 安侯建業聯合會計師事務所 | C35: KPMG 安侯建業 | D35: 林恒昇 | E35: 台北總所 | F35: 台北市信義區信義路五段7號68樓 | G35: 台北市信義區信義路五段7號68樓 | K35: 北市 | L35: 086/12/17 | M35: 1992 | N35: 2026-06-05 | O35: https://www.roccpa.org.tw/member_search/more?id=3EF3AD4D-CCD7-4D06-BCE9-5A2B117970BA
A36: 35 | B36: 安侯建業聯合會計師事務所 | C36: KPMG 安侯建業 | D36: 林棠妮 | E36: 台北總所 | F36: 台北市信義區信義路五段7號68樓 | G36: 台北市信義區信義路五段7號68樓 | I36: 110/06/28 | J36: 全聯會一字第1100265 | K36: 北市 | L36: 110/06/28 | M36: 4355 | N36: 2026-06-05 | O36: https://www.roccpa.org.tw/member_search/more?id=006B44B4-7539-4FEA-AC3A-74BB1B679C7B
A37: 36 | B37: 安侯建業聯合會計師事務所 | C37: KPMG 安侯建業 | D37: 林琇宜 | E37: 台北總所 | F37: 台北市信義區信義路五段7號68樓 | G37: 台北市信義區信義路五段7號68樓 | K37: 北市 | L37: 094/12/14 | M37: 2813 | N37: 2026-06-05 | O37: https://www.roccpa.org.tw/member_search/more?id=9D8A7F23-5B98-4C8C-B247-F6727E4D955A
A38: 37 | B38: 安侯建業聯合會計師事務所 | C38: KPMG 安侯建業 | D38: 柯有聰 | E38: 台北總所 | F38: 台北市信義區信義路五段7號68樓 | G38: 台北市信義區信義路五段7號68樓 | I38: 110/01/27 | J38: 全聯會一字第1100045 | K38: 北市 | L38: 110/01/27 | M38: 4300 | N38: 2026-06-05 | O38: https://www.roccpa.org.tw/member_search/more?id=ECA8D0D6-022B-49E9-BAE9-65919629B14A
A39: 38 | B39: 安侯建業聯合會計師事務所 | C39: KPMG 安侯建業 | D39: 梅元貞 | E39: 台北總所 | F39: 台北市信義區信義路五段7號68樓 | G39: 台北市信義區信義路五段7號68樓 | K39: 北市 | L39: 091/03/08 | M39: 2444 | N39: 2026-06-05 | O39: https://www.roccpa.org.tw/member_search/more?id=EAEDFDBF-F6FE-4CF3-A9D6-DC44FEC6AD71
A40: 39 | B40: 安侯建業聯合會計師事務所 | C40: KPMG 安侯建業 | D40: 楊樹芝 | E40: 台北總所 | F40: 台北市信義區信義路五段7號68樓 | G40: 台北市信義區信義路五段7號68樓 | I40: 104/01/28 | J40: 全聯會一字第1040057 | K40: 北市 | L40: 104/02/04 | M40: 3788 | N40: 2026-06-05 | O40: https://www.roccpa.org.tw/member_search/more?id=338CFD76-7DFF-4E3F-9267-F2B4BA1EFD24
...

Sheet EY 安永
A1: 序號 | B1: 事務所名稱 | C1: 國際品牌 | D1: 會計師姓名 | E1: 所屬分所 | F1: 辦公室地址 | G1: 主事務所地址 | H1: 分事務所地址 | I1: 執業登記日期 | J1: 執業登記文號 | K1: 所屬公會 | L1: 入會日期 | M1: 會籍編號 | N1: 資料最後更新日 | O1: 明細連結
A2: 1 | B2: 安永聯合會計師事務所 | C2: EY 安永 | D2: 何淑芬 | E2: 台北總所 | F2: 台北市信義區基隆路一段333號9樓 | G2: 台北市信義區基隆路一段333號9樓 | I2: 100/07/12 | J2: 全聯會一字第1000275 | K2: 北市 | L2: 100/08/10 | M2: 3376 | N2: 2026-06-05 | O2: https://www.roccpa.org.tw/member_search/more?id=DF676DCA-9804-485F-8CB7-70C790413E6F
A3: 2 | B3: 安永聯合會計師事務所 | C3: EY 安永 | D3: 余倩如 | E3: 台北總所 | F3: 台北市信義區基隆路一段333號9樓 | G3: 台北市信義區基隆路一段333號9樓 | I3: 103/05/16 | J3: 全聯會一字第1030202 | K3: 北市 | L3: 103/06/06 | M3: 3703 | N3: 2026-06-05 | O3: https://www.roccpa.org.tw/member_search/more?id=78CAD443-130E-4860-98C4-2131EA42F484
A4: 3 | B4: 安永聯合會計師事務所 | C4: EY 安永 | D4: 傅文芳 | E4: 台北總所 | F4: 台北市信義區基隆路一段333號9樓 | G4: 台北市信義區基隆路一段333號9樓 | K4: 北市 | L4: 086/07/08 | M4: 1923 | N4: 2026-06-05 | O4: https://www.roccpa.org.tw/member_search/more?id=17DD0B8E-A574-4C6B-ACDE-CD46521679D3
A5: 4 | B5: 安永聯合會計師事務所 | C5: EY 安永 | D5: 劉榮進 | E5: 台北總所 | F5: 台北市信義區基隆路一段333號9樓 | G5: 台北市信義區基隆路一段333號9樓 | I5: 109/03/18 | J5: 全聯會ㄧ字第1090112 | K5: 北市 | L5: 109/03/18 | M5: 4235 | N5: 2026-06-05 | O5: https://www.roccpa.org.tw/member_search/more?id=F148DA0D-CCB2-49DE-A376-B64F0B34EBC6
A6: 5 | B6: 安永聯合會計師事務所 | C6: EY 安永 | D6: 吳培源 | E6: 台北總所 | F6: 台北市信義區基隆路一段333號9樓 | G6: 台北市信義區基隆路一段333號9樓 | I6: 111/06/20 | J6: 全聯會一字第1110236 | K6: 北市 | L6: 111/06/20 | M6: 4443 | N6: 2026-06-05 | O6: https://www.roccpa.org.tw/member_search/more?id=F0B94F11-6952-4AE7-9745-BF425450DBC3
A7: 6 | B7: 安永聯合會計師事務所 | C7: EY 安永 | D7: 吳雅君 | E7: 台北總所 | F7: 台北市信義區基隆路一段333號9樓 | G7: 台北市信義區基隆路一段333號9樓 | I7: 109/11/03 | J7: 全聯會一字第1090424 | K7: 北市 | L7: 109/11/03 | M7: 4281 | N7: 2026-06-05 | O7: https://www.roccpa.org.tw/member_search/more?id=E4B561F2-68AD-4975-BFE1-3D55F95E60A3
A8: 7 | B8: 安永聯合會計師事務所 | C8: EY 安永 | D8: 呂倩雯 | E8: 台北總所 | F8: 台北市信義區基隆路一段333號9樓 | G8: 台北市信義區基隆路一段333號9樓 | I8: 107/07/02 | J8: 全聯會一字第1070276 | K8: 北市 | L8: 107/07/02 | M8: 4108 | N8: 2026-06-05 | O8: https://www.roccpa.org.tw/member_search/more?id=DA1F65BC-E49F-4C17-B1A4-679868F83AFE
A9: 8 | B9: 安永聯合會計師事務所 | C9: EY 安永 | D9: 孫孝文 | E9: 台北總所 | F9: 台北市信義區基隆路一段333號9樓 | G9: 台北市信義區基隆路一段333號9樓 | I9: 110/06/25 | J9: 全聯會一字第1100262 | K9: 中市 | L9: 110/06/25 | M9: 1033 | N9: 2026-06-05 | O9: https://www.roccpa.org.tw/member_search/more?id=39D77466-2FA5-4DAF-8C75-D65300BFFC82
A10: 9 | B10: 安永聯合會計師事務所 | C10: EY 安永 | D10: 張啓晉 | E10: 台北總所 | F10: 台北市信義區基隆路一段333號9樓 | G10: 台北市信義區基隆路一段333號9樓 | I10: 115/07/01 | J10: 全聯會一字第1150000317號 | K10: 北市 | L10: 115/07/01 | M10: 4908 | N10: 2026-07-06 | O10: https://www.roccpa.org.tw/member_search/more?id=b2fe98cd058a450cb1a5544b5ca6abe9
A11: 10 | B11: 安永聯合會計師事務所 | C11: EY 安永 | D11: 張巧穎 | E11: 台北總所 | F11: 台北市信義區基隆路一段333號9樓 | G11: 台北市信義區基隆路一段333號9樓 | I11: 110/06/25 | J11: 全聯會一字第1100261 | K11: 北市 | L11: 110/06/25 | M11: 4354 | N11: 2026-06-05 | O11: https://www.roccpa.org.tw/member_search/more?id=262E6C49-4F1D-4500-AA59-BC1E6C5B8C12
A12: 11 | B12: 安永聯合會計師事務所 | C12: EY 安永 | D12: 張志銘 | E12: 台北總所 | F12: 台北市信義區基隆路一段333號9樓 | G12: 台北市信義區基隆路一段333號9樓 | K12: 北市 | L12: 091/12/16 | M12: 2525 | N12: 2026-06-05 | O12: https://www.roccpa.org.tw/member_search/more?id=6CB91D23-954D-428B-AA96-CE8D97FEECE8
A13: 12 | B13: 安永聯合會計師事務所 | C13: EY 安永 | D13: 張正道 | E13: 台北總所 | F13: 台北市信義區基隆路一段333號9樓 | G13: 台北市信義區基隆路一段333號9樓 | I13: 103/05/16 | J13: 全聯會一字第1030203 | K13: 北市 | L13: 103/06/06 | M13: 3702 | N13: 2026-06-05 | O13: https://www.roccpa.org.tw/member_search/more?id=E81E11FD-6DF8-4D32-89A2-6E4349FE0F34
A14: 13 | B14: 安永聯合會計師事務所 | C14: EY 安永 | D14: 徐榮煌 | E14: 台北總所 | F14: 台北市信義區基隆路一段333號9樓 | G14: 台北市信義區基隆路一段333號9樓 | K14: 北市 | L14: 088/10/14 | M14: 2205 | N14: 2026-06-05 | O14: https://www.roccpa.org.tw/member_search/more?id=1E8C6C56-CDA8-4B33-9F40-BF1009B96E2C
A15: 14 | B15: 安永聯合會計師事務所 | C15: EY 安永 | D15: 曾于哲 | E15: 台北總所 | F15: 台北市信義區基隆路一段333號9樓 | G15: 台北市信義區基隆路一段333號9樓 | I15: 105/09/10 | J15: 全聯會一字第1050408 | K15: 北市 | L15: 105/10/12 | M15: 3968 | N15: 2026-06-05 | O15: https://www.roccpa.org.tw/member_search/more?id=38E5AC40-C09F-4386-A779-D0BB64F63331
A16: 15 | B16: 安永聯合會計師事務所 | C16: EY 安永 | D16: 李育儒 | E16: 台北總所 | F16: 台北市信義區基隆路一段333號9樓 | G16: 台北市信義區基隆路一段333號9樓 | I16: 109/10/13 | J16: 全聯會一字第1090404 | K16: 北市 | L16: 109/10/13 | M16: 4278 | N16: 2026-06-05 | O16: https://www.roccpa.org.tw/member_search/more?id=AC5FBF1E-88B7-4E7A-A0F1-89188D4BB29F
A17: 16 | B17: 安永聯合會計師事務所 | C17: EY 安永 | D17: 林世寰 | E17: 台北總所 | F17: 台北市信義區基隆路一段333號9樓 | G17: 台北市信義區基隆路一段333號9樓 | I17: 112/06/22 | J17: 全聯會一字第1120256 | K17: 北市 | L17: 112/06/29 | M17: 4546 | N17: 2026-06-05 | O17: https://www.roccpa.org.tw/member_search/more?id=20C1B710-9337-4FAC-8C1D-253B480CC378
A18: 17 | B18: 安永聯合會計師事務所 | C18: EY 安永 | D18: 林孟賢 | E18: 台北總所 | F18: 台北市信義區基隆路一段333號9樓 | G18: 台北市信義區基隆路一段333號9樓 | I18: 113/07/15 | J18: 全聯會一字第1130000327號 | K18: 北市 | L18: 113/07/15 | M18: 4654 | N18: 2026-06-05 | O18: https://www.roccpa.org.tw/member_search/more?id=9253BE37-E344-4F3E-817F-4CDA88599380
A19: 18 | B19: 安永聯合會計師事務所 | C19: EY 安永 | D19: 林宜賢 | E19: 台北總所 | F19: 台北市信義區基隆路一段333號9樓 | G19: 台北市信義區基隆路一段333號9樓 | K19: 北市 | L19: 090/03/15 | M19: 2348 | N19: 2026-06-05 | O19: https://www.roccpa.org.tw/member_search/more?id=4A0CF9AA-4A27-4E2A-811D-59A4EBF4D0DF
A20: 19 | B20: 安永聯合會計師事務所 | C20: EY 安永 | D20: 林志仁 | E20: 台北總所 | F20: 台北市信義區基隆路一段333號9樓 | G20: 台北市信義區基隆路一段333號9樓 | I20: 111/06/20 | J20: 全聯會一字第1110234 | K20: 北市 | L20: 111/06/20 | M20: 4441 | N20: 2026-06-05 | O20: https://www.roccpa.org.tw/member_search/more?id=FC149136-F393-4AC0-8DDF-9C3806B20A0E
A21: 20 | B21: 安永聯合會計師事務所 | C21: EY 安永 | D21: 林志翔 | E21: 台北總所 | F21: 台北市信義區基隆路一段333號9樓 | G21: 台北市信義區基隆路一段333號9樓 | I21: 103/05/16 | J21: 全聯會一字第1030201 | K21: 北市 | L21: 103/06/06 | M21: 3705 | N21: 2026-06-05 | O21: https://www.roccpa.org.tw/member_search/more?id=8328EF3A-AAE7-490E-8625-870D6E74A67D
A22: 21 | B22: 安永聯合會計師事務所 | C22: EY 安永 | D22: 林秀青 | E22: 台北總所 | F22: 台北市信義區基隆路一段333號9樓 | G22: 台北市信義區基隆路一段333號9樓 | I22: 114/07/01 | J22: 全聯會一字第1140000260號 | K22: 北市 | L22: 114/07/01 | M22: 4734 | N22: 2026-06-05 | O22: https://www.roccpa.org.tw/member_search/more?id=651C85C1-EFE6-465E-A7D1-C64123A7BFCE
A23: 22 | B23: 安永聯合會計師事務所 | C23: EY 安永 | D23: 林素雯 | E23: 台北總所 | F23: 台北市信義區基隆路一段333號9樓 | G23: 台北市信義區基隆路一段333號9樓 | I23: 099/12/31 | J23: 全聯會一字第09900645 | K23: 北市 | L23: 100/01/13 | M23: 3306 | N23: 2026-06-05 | O23: https://www.roccpa.org.tw/member_search/more?id=C5B224F3-CE49-40E3-85BB-50258D495942
A24: 23 | B24: 安永聯合會計師事務所 | C24: EY 安永 | D24: 林鈺芳 | E24: 台北總所 | F24: 台北市信義區基隆路一段333號9樓 | G24: 台北市信義區基隆路一段333號9樓 | I24: 114/07/01 | J24: 全聯會一字第1140000261號 | K24: 北市 | L24: 114/07/01 | M24: 4735 | N24: 2026-06-05 | O24: https://www.roccpa.org.tw/member_search/more?id=A30FC7CD-E0EF-421F-BE1B-5F170AF8835D
A25: 24 | B25: 安永聯合會計師事務所 | C25: EY 安永 | D25: 楊弘斌 | E25: 台北總所 | F25: 台北市信義區基隆路一段333號9樓 | G25: 台北市信義區基隆路一段333號9樓 | I25: 111/06/20 | J25: 全聯會一字第1110235 | K25: 北市 | L25: 111/06/20 | M25: 4442 | N25: 2026-06-05 | O25: https://www.roccpa.org.tw/member_search/more?id=D7835F4B-583F-4EC5-BE2A-BA2B0C1543DD
A26: 25 | B26: 安永聯合會計師事務所 | C26: EY 安永 | D26: 溫珮絃 | E26: 台北總所 | F26: 台北市信義區基隆路一段333號9樓 | G26: 台北市信義區基隆路一段333號9樓 | I26: 113/07/15 | J26: 全聯會一字第1130000328號 | K26: 北市 | L26: 113/07/15 | M26: 4655 | N26: 2026-06-05 | O26: https://www.roccpa.org.tw/member_search/more?id=EAC03D03-D2E1-43BD-B153-874CD61392D7
A27: 26 | B27: 安永聯合會計師事務所 | C27: EY 安永 | D27: 王彥鈞 | E27: 台北總所 | F27: 台北市信義區基隆路一段333號9樓 | G27: 台北市信義區基隆路一段333號9樓 | K27: 北市 | L27: 091/11/27 | M27: 2508 | N27: 2026-06-05 | O27: https://www.roccpa.org.tw/member_search/more?id=424B077C-8C90-48BD-817A-1BA0D1EA4376
A28: 27 | B28: 安永聯合會計師事務所 | C28: EY 安永 | D28: 王慕凡 | E28: 台北總所 | F28: 台北市信義區基隆路一段333號9樓 | G28: 台北市信義區基隆路一段333號9樓 | I28: 101/11/08 | J28: 全聯會一字第1010402 | K28: 北市 | L28: 113/01/05 | M28: 4586 | N28: 2026-06-05 | O28: https://www.roccpa.org.tw/member_search/more?id=B14EC97F-D414-4092-B045-FF107AA1A6F1
A29: 28 | B29: 安永聯合會計師事務所 | C29: EY 安永 | D29: 王瑄瑄 | E29: 台北總所 | F29: 台北市信義區基隆路一段333號9樓 | G29: 台北市信義區基隆路一段333號9樓 | I29: 105/08/17 | J29: 全聯會一字第1050361 | K29: 北市 | L29: 105/10/12 | M29: 3965 | N29: 2026-06-05 | O29: https://www.roccpa.org.tw/member_search/more?id=DA4D0199-B910-4603-B86F-91699DC5BE2A
A30: 29 | B30: 安永聯合會計師事務所 | C30: EY 安永 | D30: 王甯寬 | E30: 台北總所 | F30: 台北市信義區基隆路一段333號9樓 | G30: 台北市信義區基隆路一段333號9樓 | I30: 114/07/01 | J30: 全聯會一字第1140000259號 | K30: 北市 | L30: 114/07/01 | M30: 4733 | N30: 2026-06-05 | O30: https://www.roccpa.org.tw/member_search/more?id=27C067B7-7EBA-499B-89DC-48EA38B0C431
A31: 30 | B31: 安永聯合會計師事務所 | C31: EY 安永 | D31: 葉柏良 | E31: 台北總所 | F31: 台北市信義區基隆路一段333號9樓 | G31: 台北市信義區基隆路一段333號9樓 | I31: 113/07/15 | J31: 全聯會一字第1130000329號 | K31: 北市 | L31: 113/07/15 | M31: 4656 | N31: 2026-06-05 | O31: https://www.roccpa.org.tw/member_search/more?id=7961944C-E8DF-48AF-A3AB-DC5DBECC7DF7
A32: 31 | B32: 安永聯合會計師事務所 | C32: EY 安永 | D32: 蔡雅萍 | E32: 台北總所 | F32: 台北市信義區基隆路一段333號9樓 | G32: 台北市信義區基隆路一段333號9樓 | I32: 103/05/16 | J32: 全聯會一字第1030199 | K32: 北市 | L32: 103/06/06 | M32: 3706 | N32: 2026-06-05 | O32: https://www.roccpa.org.tw/member_search/more?id=00A112ED-121D-4894-A56C-E7CD88466C25
A33: 32 | B33: 安永聯合會計師事務所 | C33: EY 安永 | D33: 許廷安 | E33: 台北總所 | F33: 台北市信義區基隆路一段333號9樓 | G33: 台北市信義區基隆路一段333號9樓 | I33: 111/06/20 | J33: 全聯會一字第1110233 | K33: 北市 | L33: 111/06/20 | M33: 4440 | N33: 2026-06-05 | O33: https://www.roccpa.org.tw/member_search/more?id=C75F0E87-8C11-48DA-8ECF-145C35BF54CD
A34: 33 | B34: 安永聯合會計師事務所 | C34: EY 安永 | D34: 許新民 | E34: 台北總所 | F34: 台北市信義區基隆路一段333號9樓 | G34: 台北市信義區基隆路一段333號9樓 | K34: 北市 | L34: 085/12/04 | M34: 1867 | N34: 2026-06-05 | O34: https://www.roccpa.org.tw/member_search/more?id=9ABDFCED-FC8A-4354-BC64-E1A91D2E32A7
A35: 34 | B35: 安永聯合會計師事務所 | C35: EY 安永 | D35: 謝勝安 | E35: 台北總所 | F35: 台北市信義區基隆路一段333號9樓 | G35: 台北市信義區基隆路一段333號9樓 | I35: 105/08/17 | J35: 全聯會一字第1050362 | K35: 北市 | L35: 105/10/12 | M35: 3966 | N35: 2026-06-05 | O35: https://www.roccpa.org.tw/member_search/more?id=875A59F4-8934-49B7-B88E-F70BC98545FD
A36: 35 | B36: 安永聯合會計師事務所 | C36: EY 安永 | D36: 郭紹彬 | E36: 台北總所 | F36: 台北市信義區基隆路一段333號9樓 | G36: 台北市信義區基隆路一段333號9樓 | K36: 北市 | L36: 091/10/01 | M36: 2489 | N36: 2026-06-05 | O36: https://www.roccpa.org.tw/member_search/more?id=D2935B19-212E-48B8-93AA-144265180884
A37: 36 | B37: 安永聯合會計師事務所 | C37: EY 安永 | D37: 陳人理 | E37: 台北總所 | F37: 台北市信義區基隆路一段333號9樓 | G37: 台北市信義區基隆路一段333號9樓 | I37: 115/07/01 | J37: 全聯會一字第1150000318號 | K37: 北市 | L37: 115/07/01 | M37: 4909 | N37: 2026-07-06 | O37: https://www.roccpa.org.tw/member_search/more?id=1b4536c62ba64e80b04d5ef31cf95423
